Workbook
Name AAAAAAAAA1: Comparison!$ALA$1
Name Dividend_Yield_pa: Inputs!$C$16
Name Entry_Driver: Inputs!$C$14
Name Entry_Financing_Rate: Inputs!$C$21
Name Gross_Leverage: Inputs!$C$11
Name Initial_Loan: Inputs!$C$13
Name Initial_Margin_Rate: Inputs!$C$18
Name Initial_Margin_Req: Inputs!$C$19
Name Initial_Position_Value: Inputs!$C$12
Name Liquidation_Slippage: Inputs!$C$17
Name Liquidity_Reserve_0: Inputs!$C$10
Name Period_Length_Yrs: Inputs!$C$7
Name Period_Unit: Inputs!$C$5
Name Periods_per_Year: Inputs!$C$6
Name Sell_To_Fund: Case1_Calm!$D$4
Name Sell_To_Fund: Case2A_Ruin_ConstRates!$D$4
Name Sell_To_Fund: Case2B_Ruin_ChangingRates!$D$4
Name Sell_To_Fund: Case2C_Changing_SellToFund!$D$4
Name Starting_Equity: Inputs!$C$9
Name Target_Driver: Inputs!$C$15

Sheet README
B1: Rick Guerin: leveraged equity investing - plain-vanilla margin account version
B2: Simplified companion to 22_Rick_Guerin_Margin.xlsx. Three ruin cases: constant rates, changing rates, and changing rates with partial sales. Illustrative, not historical data.
B4: Contents (click to jump)
B5: The trade
B6: How this differs from file 22
B7: Case 1 - Calm
B8: Case 2A - Ruin with constant margin and financing rates
B9: Case 2B - Ruin with changing margin and financing rates
B10: Case 2C - Changing rates, sell to fund
B11: How the model works (each period)
B12: Sheets
B13: Colour legend
... B55: Stylised numbers. No withdrawals, no re-leveraging when prices rise, no tax or commissions. Maintenance margin is applied to the end-of-period market value. A 15% liquidation cost is assumed if the position is force-sold.

Sheet Inputs
A1: Inputs and assumptions
A2: Blue = input; black = formula. Every input is a named range (column E). Stylised teaching numbers loosely inspired by the 1973-74 bear market, not historical data.
B4: Parameter | C4: Value | D4: Note | E4: Range name (used in formulas)
B5: Period unit | C5: Quarter | D5: Each row of the case sheets is one period | E5: Period_Unit
B6: Periods per year | C6: 4 | D6: Converts annual rates to a period rate | E6: Periods_per_Year
B7: Period length (years) | C7: =1/Periods_per_Year -> 0.25 | D7: Formula | E7: Period_Length_Yrs
B9: Starting equity ($mm) | C9: 100 | D9: Own capital put into the margin account | E9: Starting_Equity
B10: Liquidity reserve ($mm) | C10: 10 | D10: Cash available to meet margin calls. Key lever. | E10: Liquidity_Reserve_0
B11: Leverage (position value / equity) | C11: 1.8 | D11: As in file 22. Key lever. | E11: Gross_Leverage
B12: Initial position value ($mm) | C12: =Starting_Equity*Gross_Leverage -> 180 | D12: Formula: market value of the shares bought | E12: Initial_Position_Value
B13: Initial margin loan ($mm) | C13: =Initial_Position_Value-Starting_Equity -> 80 | D13: Formula: borrowed from the broker | E13: Initial_Loan
B14: Driver level at entry | C14: 100 | D14: Equity index / portfolio level, rebased to 100 | E14: Entry_Driver
B15: Target driver level (thesis pays) | C15: 165 | D15: Case 1 and Case 2 paths both end here | E15: Target_Driver
B16: Dividend yield (p.a.) | C16: 0.03 | D16: Dividends received are used to reduce the loan | E16: Dividend_Yield_pa
B17: Forced-liquidation cost (% of position value) | C17: 0.15 | D17: Fire-sale discount and impact if the position is dumped to meet a call it cannot fund (illiquid 1974 market) | E17: Liquidation_Slippage
B18: Initial margin (maintenance) rate (% of position value) | C18: 0.3 | D18: Equity must stay at least this share of the position's market value. Key lever. | E18: Initial_Margin_Rate
B19: Initial margin required ($mm) | C19: =Initial_Margin_Rate*Initial_Position_Value -> 54 | D19: Formula | E19: Initial_Margin_Req
B20: Check: equity covers initial margin? | C20: =IF(Starting_Equity>=Initial_Margin_Req,"OK","INSUFFICIENT EQUITY") -> OK | D20: Formula
B21: Loan interest rate at entry (p.a.) | C21: 0.08 | D21: Paths over time are on the case sheets | E21: Entry_Financing_Rate

Sheet Case1_Calm
A1: Rick Guerin margin trade (plain vanilla) - Case 1 - Calm / expected path
A2: Same structure on every case sheet; only the blue driver, margin-rate and loan-rate paths differ. P&L = position value x % change in the driver. $mm unless stated.
A3: Equities compound at about 6.5% a year with small wiggles. Equity in the margin account always exceeds the maintenance requirement, no margin call is ever made, the reserve is untouched and the investor keeps the full gain on the borrowed money.
A4: Sell shares to fund an unmet call? 1 = yes, 0 = no (full liquidation) | D4: 0
A5: Key results
A6: Starting capital (equity + reserve) | D6: =Starting_Equity+Liquidity_Reserve_0 -> 110
A7: Ending net worth | D7: =Z59 -> 231.13294
A8: Total return | D8: =D7/D6-1 -> 1.1012086
A9: Maximum drawdown of net worth | D9: =MIN(AE27:AE59) -> -0.0040775295
A10: Number of margin calls | D10: =COUNTIF(Q28:Q59,">0") -> 0
A11: Total cash posted to margin | D11: =SUM(R28:R59) -> 0
A12: Lowest liquidity reserve | D12: =MIN(W27:W59) -> 10
A13: First default period | D13: =IFERROR(INDEX(A27:A59,MATCH(1,AF27:AF59,0)),"None") -> None
A14: Outcome | D14: =IF(ISNUMBER(D13),"RUIN: forced out, "&LOWER(Period_Unit)&" "&D13,IF(D21>0,"SURVIVED: "&D21&" partial sale"&IF(D21>1,"s",""),"SURVIVED to convergence")) -> SURVIVED to convergence
A15: Peak margin rate | D15: =MAX(D27:D59) -> 0.3
A16: Peak loan interest rate | D16: =MAX(E27:E59) -> 0.08
A17: Net worth if never forced out (shadow) | D17: =AC59 -> 231.13294
A18: Shadow return | D18: =D17/D6-1 -> 1.1012086
A19: Thesis eventually proven right? | D19: =IF(D17>D6,IF(ISNUMBER(D13),"Yes - but only after forced exit","Yes"),"No") -> Yes
A20: Value lost to forced liquidation | D20: =D17-D7 -> 0
A21: Partial sales (count) | D21: =SUM(AI28:AI59) -> 0
A22: Shares sold to meet calls ($mm) | D22: =SUM(AG28:AG59) -> 0
A23: Liquidation cost paid ($mm) | D23: =SUM(T28:T59) -> 0
A25: Period-by-period simulation
A26: t | B26: Period | C26: Driver (index) | D26: Margin rate (% of position) | E26: Loan interest rate p.a. | F26: % change in driver | G26: Position live at start (1/0) | H26: Exposure: position value at start | I26: Price P&L = exposure x % change | J26: Dividends | K26: Loan interest | L26: Net P&L | M26: Position value at end | N26: Loan before call | O26: Equity before call | P26: Required margin | Q26: Margin call | R26: Cash paid from reserve | S26: Shortfall (unmet call) | T26: Forced-liquidation cost | U26: Equity after call | V26: Loan after call | W26: Liquidity reserve | X26: Position live at end (1/0) | Y26: Status | Z26: Net worth (equity + reserve) | AA26: Shadow position value | AB26: Shadow loan | AC26: Shadow net worth (never forced out) | AD26: Running peak of net worth | AE26: Drawdown | AF26: Default flag | AG26: Shares sold to meet call ($mm of position) | AH26: Position value after call (carried forward) | AI26: Partial-sale flag
A27: 0 | B27: =Period_Unit&" "&A27 -> Quarter 0 | C27: =Entry_Driver -> 100 | D27: =Initial_Margin_Rate -> 0.3 | E27: =Entry_Financing_Rate -> 0.08 | G27: 1 | M27: =Initial_Position_Value -> 180 | U27: =Starting_Equity -> 100 | V27: =Initial_Loan -> 80 | W27: =Liquidity_Reserve_0 -> 10 | X27: 1 | Y27: Position opened | Z27: =U27+W27 -> 110 | AA27: =Initial_Position_Value -> 180 | AB27: =Initial_Loan -> 80 | AC27: =AA27-AB27+Liquidity_Reserve_0 -> 110 | AD27: =Z27 -> 110 | AE27: 0 | AF27: 0 | AG27: 0 | AH27: =Initial_Position_Value -> 180 | AI27: 0
A28: 1 | B28: =Period_Unit&" "&A28 -> Quarter 1 | C28: 102.7 | D28: 0.3 | E28: 0.08 | F28: =C28/C27-1 -> 0.027 | G28: =X27 -> 1 | H28: =G28*AH27 -> 180 | I28: =H28*F28 -> 4.86 | J28: =H28*Dividend_Yield_pa*Period_Length_Yrs -> 1.35 | K28: =G28*V27*E28*Period_Length_Yrs -> 1.6 | L28: =I28+J28-K28 -> 4.61 | M28: =H28*(1+F28) -> 184.86 | N28: =G28*(V27+K28-J28) -> 80.25 | O28: =M28-N28 -> 104.61 | P28: =D28*M28 -> 55.458 | Q28: =MAX(0,P28-O28) -> 0 | R28: =MIN(Q28,W27) -> 0 | S28: =Q28-R28 -> 0 | T28: =IF(S28>0,Liquidation_Slippage*AG28,0) -> 0 | U28: =IF(G28=0,U27,IF(S28>0,MAX(0,O28+R28-T28),O28+R28)) -> 104.61 | V28: =IF(G28=0,0,IF(S28>0,IF(AG28<M28,N28-R28-AG28*(1-Liquidation_Slippage),0),N28-R28)) -> 80.25 | W28: =W27-R28 -> 10 | X28: =IF(AND(G28=1,OR(S28=0,AG28<M28)),1,0) -> 1 | Y28: =IF(G28=0,"Liquidated earlier",IF(AF28=1,"DEFAULT - forced liquidation",IF(AI28=1,"Shares sold to meet call",IF(Q28>0,"Margin call met from reserve","OK")))) -> OK | Z28: =U28+W28 -> 114.61 | AA28: =AA27*(1+F28) -> 184.86 | AB28: =AB27*(1+E28*Period_Length_Yrs)-AA27*Dividend_Yield_pa*Period_Length_Yrs -> 80.25 | AC28: =AA28-AB28+Liquidity_Reserve_0 -> 114.61 | AD28: =MAX(AD27,Z28) -> 114.61 | AE28: =Z28/AD28-1 -> 0 | AF28: =IF(AND(S28>0,AG28>=M28),1,0) -> 0 | AG28: =IF(S28>0,IF(AND(Sell_To_Fund=1,D28>Liquidation_Slippage),MIN(M28,S28/(D28-Liquidation_Slippage)),M28),0) -> 0 | AH28: =IF(G28=0,0,IF(S28>0,IF(AG28<M28,M28-AG28,0),M28)) -> 184.86 | AI28: =IF(AND(S28>0,AG28<M28),1,0) -> 0
A29: 2 | B29: =Period_Unit&" "&A29 -> Quarter 2 | C29: 102.62 | D29: 0.3 | E29: 0.08 | F29: =C29/C28-1 -> -0.00077896787 | G29: =X28 -> 1 | H29: =G29*AH28 -> 184.86 | I29: =H29*F29 -> -0.144 | J29: =H29*Dividend_Yield_pa*Period_Length_Yrs -> 1.38645 | K29: =G29*V28*E29*Period_Length_Yrs -> 1.605 | L29: =I29+J29-K29 -> -0.36255 | M29: =H29*(1+F29) -> 184.716 | N29: =G29*(V28+K29-J29) -> 80.46855 | O29: =M29-N29 -> 104.24745 | P29: =D29*M29 -> 55.4148 | Q29: =MAX(0,P29-O29) -> 0 | R29: =MIN(Q29,W28) -> 0 | S29: =Q29-R29 -> 0 | T29: =IF(S29>0,Liquidation_Slippage*AG29,0) -> 0 | U29: =IF(G29=0,U28,IF(S29>0,MAX(0,O29+R29-T29),O29+R29)) -> 104.24745 | V29: =IF(G29=0,0,IF(S29>0,IF(AG29<M29,N29-R29-AG29*(1-Liquidation_Slippage),0),N29-R29)) -> 80.46855 | W29: =W28-R29 -> 10 | X29: =IF(AND(G29=1,OR(S29=0,AG29<M29)),1,0) -> 1 | Y29: =IF(G29=0,"Liquidated earlier",IF(AF29=1,"DEFAULT - forced liquidation",IF(AI29=1,"Shares sold to meet call",IF(Q29>0,"Margin call met from reserve","OK")))) -> OK | Z29: =U29+W29 -> 114.24745 | AA29: =AA28*(1+F29) -> 184.716 | AB29: =AB28*(1+E29*Period_Length_Yrs)-AA28*Dividend_Yield_pa*Period_Length_Yrs -> 80.46855 | AC29: =AA29-AB29+Liquidity_Reserve_0 -> 114.24745 | AD29: =MAX(AD28,Z29) -> 114.61 | AE29: =Z29/AD29-1 -> -0.0031633365 | AF29: =IF(AND(S29>0,AG29>=M29),1,0) -> 0 | AG29: =IF(S29>0,IF(AND(Sell_To_Fund=1,D29>Liquidation_Slippage),MIN(M29,S29/(D29-Liquidation_Slippage)),M29),0) -> 0 | AH29: =IF(G29=0,0,IF(S29>0,IF(AG29<M29,M29-AG29,0),M29)) -> 184.716 | AI29: =IF(AND(S29>0,AG29<M29),1,0) -> 0
A30: 3 | B30: =Period_Unit&" "&A30 -> Quarter 3 | C30: 105.1 | D30: 0.3 | E30: 0.08 | F30: =C30/C29-1 -> 0.024166829 | G30: =X29 -> 1 | H30: =G30*AH29 -> 184.716 | I30: =H30*F30 -> 4.464 | J30: =H30*Dividend_Yield_pa*Period_Length_Yrs -> 1.38537 | K30: =G30*V29*E30*Period_Length_Yrs -> 1.609371 | L30: =I30+J30-K30 -> 4.239999 | M30: =H30*(1+F30) -> 189.18 | N30: =G30*(V29+K30-J30) -> 80.692551 | O30: =M30-N30 -> 108.48745 | P30: =D30*M30 -> 56.754 | Q30: =MAX(0,P30-O30) -> 0 | R30: =MIN(Q30,W29) -> 0 | S30: =Q30-R30 -> 0 | T30: =IF(S30>0,Liquidation_Slippage*AG30,0) -> 0 | U30: =IF(G30=0,U29,IF(S30>0,MAX(0,O30+R30-T30),O30+R30)) -> 108.48745 | V30: =IF(G30=0,0,IF(S30>0,IF(AG30<M30,N30-R30-AG30*(1-Liquidation_Slippage),0),N30-R30)) -> 80.692551 | W30: =W29-R30 -> 10 | X30: =IF(AND(G30=1,OR(S30=0,AG30<M30)),1,0) -> 1 | Y30: =IF(G30=0,"Liquidated earlier",IF(AF30=1,"DEFAULT - forced liquidation",IF(AI30=1,"Shares sold to meet call",IF(Q30>0,"Margin call met from reserve","OK")))) -> OK | Z30: =U30+W30 -> 118.48745 | AA30: =AA29*(1+F30) -> 189.18 | AB30: =AB29*(1+E30*Period_Length_Yrs)-AA29*Dividend_Yield_pa*Period_Length_Yrs -> 80.692551 | AC30: =AA30-AB30+Liquidity_Reserve_0 -> 118.48745 | AD30: =MAX(AD29,Z30) -> 118.48745 | AE30: =Z30/AD30-1 -> 0 | AF30: =IF(AND(S30>0,AG30>=M30),1,0) -> 0 | AG30: =IF(S30>0,IF(AND(Sell_To_Fund=1,D30>Liquidation_Slippage),MIN(M30,S30/(D30-Liquidation_Slippage)),M30),0) -> 0 | AH30: =IF(G30=0,0,IF(S30>0,IF(AG30<M30,M30-AG30,0),M30)) -> 189.18 | AI30: =IF(AND(S30>0,AG30<M30),1,0) -> 0
A31: 4 | B31: =Period_Unit&" "&A31 -> Quarter 4 | C31: 106.9 | D31: 0.3 | E31: 0.08 | F31: =C31/C30-1 -> 0.017126546 | G31: =X30 -> 1 | H31: =G31*AH30 -> 189.18 | I31: =H31*F31 -> 3.24 | J31: =H31*Dividend_Yield_pa*Period_Length_Yrs -> 1.41885 | K31: =G31*V30*E31*Period_Length_Yrs -> 1.613851 | L31: =I31+J31-K31 -> 3.044999 | M31: =H31*(1+F31) -> 192.42 | N31: =G31*(V30+K31-J31) -> 80.887552 | O31: =M31-N31 -> 111.53245 | P31: =D31*M31 -> 57.726 | Q31: =MAX(0,P31-O31) -> 0 | R31: =MIN(Q31,W30) -> 0 | S31: =Q31-R31 -> 0 | T31: =IF(S31>0,Liquidation_Slippage*AG31,0) -> 0 | U31: =IF(G31=0,U30,IF(S31>0,MAX(0,O31+R31-T31),O31+R31)) -> 111.53245 | V31: =IF(G31=0,0,IF(S31>0,IF(AG31<M31,N31-R31-AG31*(1-Liquidation_Slippage),0),N31-R31)) -> 80.887552 | W31: =W30-R31 -> 10 | X31: =IF(AND(G31=1,OR(S31=0,AG31<M31)),1,0) -> 1 | Y31: =IF(G31=0,"Liquidated earlier",IF(AF31=1,"DEFAULT - forced liquidation",IF(AI31=1,"Shares sold to meet call",IF(Q31>0,"Margin call met from reserve","OK")))) -> OK | Z31: =U31+W31 -> 121.53245 | AA31: =AA30*(1+F31) -> 192.42 | AB31: =AB30*(1+E31*Period_Length_Yrs)-AA30*Dividend_Yield_pa*Period_Length_Yrs -> 80.887552 | AC31: =AA31-AB31+Liquidity_Reserve_0 -> 121.53245 | AD31: =MAX(AD30,Z31) -> 121.53245 | AE31: =Z31/AD31-1 -> 0 | AF31: =IF(AND(S31>0,AG31>=M31),1,0) -> 0 | AG31: =IF(S31>0,IF(AND(Sell_To_Fund=1,D31>Liquidation_Slippage),MIN(M31,S31/(D31-Liquidation_Slippage)),M31),0) -> 0 | AH31: =IF(G31=0,0,IF(S31>0,IF(AG31<M31,M31-AG31,0),M31)) -> 192.42 | AI31: =IF(AND(S31>0,AG31<M31),1,0) -> 0
A32: 5 | B32: =Period_Unit&" "&A32 -> Quarter 5 | C32: 108.95 | D32: 0.3 | E32: 0.08 | F32: =C32/C31-1 -> 0.019176801 | G32: =X31 -> 1 | H32: =G32*AH31 -> 192.42 | I32: =H32*F32 -> 3.69 | J32: =H32*Dividend_Yield_pa*Period_Length_Yrs -> 1.44315 | K32: =G32*V31*E32*Period_Length_Yrs -> 1.617751 | L32: =I32+J32-K32 -> 3.515399 | M32: =H32*(1+F32) -> 196.11 | N32: =G32*(V31+K32-J32) -> 81.062153 | O32: =M32-N32 -> 115.04785 | P32: =D32*M32 -> 58.833 | Q32: =MAX(0,P32-O32) -> 0 | R32: =MIN(Q32,W31) -> 0 | S32: =Q32-R32 -> 0 | T32: =IF(S32>0,Liquidation_Slippage*AG32,0) -> 0 | U32: =IF(G32=0,U31,IF(S32>0,MAX(0,O32+R32-T32),O32+R32)) -> 115.04785 | V32: =IF(G32=0,0,IF(S32>0,IF(AG32<M32,N32-R32-AG32*(1-Liquidation_Slippage),0),N32-R32)) -> 81.062153 | W32: =W31-R32 -> 10 | X32: =IF(AND(G32=1,OR(S32=0,AG32<M32)),1,0) -> 1 | Y32: =IF(G32=0,"Liquidated earlier",IF(AF32=1,"DEFAULT - forced liquidation",IF(AI32=1,"Shares sold to meet call",IF(Q32>0,"Margin call met from reserve","OK")))) -> OK | Z32: =U32+W32 -> 125.04785 | AA32: =AA31*(1+F32) -> 196.11 | AB32: =AB31*(1+E32*Period_Length_Yrs)-AA31*Dividend_Yield_pa*Period_Length_Yrs -> 81.062153 | AC32: =AA32-AB32+Liquidity_Reserve_0 -> 125.04785 | AD32: =MAX(AD31,Z32) -> 125.04785 | AE32: =Z32/AD32-1 -> 0 | AF32: =IF(AND(S32>0,AG32>=M32),1,0) -> 0 | AG32: =IF(S32>0,IF(AND(Sell_To_Fund=1,D32>Liquidation_Slippage),MIN(M32,S32/(D32-Liquidation_Slippage)),M32),0) -> 0 | AH32: =IF(G32=0,0,IF(S32>0,IF(AG32<M32,M32-AG32,0),M32)) -> 196.11 | AI32: =IF(AND(S32>0,AG32<M32),1,0) -> 0
A33: 6 | B33: =Period_Unit&" "&A33 -> Quarter 6 | C33: 109.45 | D33: 0.3 | E33: 0.08 | F33: =C33/C32-1 -> 0.0045892611 | G33: =X32 -> 1 | H33: =G33*AH32 -> 196.11 | I33: =H33*F33 -> 0.9 | J33: =H33*Dividend_Yield_pa*Period_Length_Yrs -> 1.470825 | K33: =G33*V32*E33*Period_Length_Yrs -> 1.6212431 | L33: =I33+J33-K33 -> 0.74958194 | M33: =H33*(1+F33) -> 197.01 | N33: =G33*(V32+K33-J33) -> 81.212571 | O33: =M33-N33 -> 115.79743 | P33: =D33*M33 -> 59.103 | Q33: =MAX(0,P33-O33) -> 0 | R33: =MIN(Q33,W32) -> 0 | S33: =Q33-R33 -> 0 | T33: =IF(S33>0,Liquidation_Slippage*AG33,0) -> 0 | U33: =IF(G33=0,U32,IF(S33>0,MAX(0,O33+R33-T33),O33+R33)) -> 115.79743 | V33: =IF(G33=0,0,IF(S33>0,IF(AG33<M33,N33-R33-AG33*(1-Liquidation_Slippage),0),N33-R33)) -> 81.212571 | W33: =W32-R33 -> 10 | X33: =IF(AND(G33=1,OR(S33=0,AG33<M33)),1,0) -> 1 | Y33: =IF(G33=0,"Liquidated earlier",IF(AF33=1,"DEFAULT - forced liquidation",IF(AI33=1,"Shares sold to meet call",IF(Q33>0,"Margin call met from reserve","OK")))) -> OK | Z33: =U33+W33 -> 125.79743 | AA33: =AA32*(1+F33) -> 197.01 | AB33: =AB32*(1+E33*Period_Length_Yrs)-AA32*Dividend_Yield_pa*Period_Length_Yrs -> 81.212571 | AC33: =AA33-AB33+Liquidity_Reserve_0 -> 125.79743 | AD33: =MAX(AD32,Z33) -> 125.79743 | AE33: =Z33/AD33-1 -> 0 | AF33: =IF(AND(S33>0,AG33>=M33),1,0) -> 0 | AG33: =IF(S33>0,IF(AND(Sell_To_Fund=1,D33>Liquidation_Slippage),MIN(M33,S33/(D33-Liquidation_Slippage)),M33),0) -> 0 | AH33: =IF(G33=0,0,IF(S33>0,IF(AG33<M33,M33-AG33,0),M33)) -> 197.01 | AI33: =IF(AND(S33>0,AG33<M33),1,0) -> 0
A34: 7 | B34: =Period_Unit&" "&A34 -> Quarter 7 | C34: 111.91 | D34: 0.3 | E34: 0.08 | F34: =C34/C33-1 -> 0.022476016 | G34: =X33 -> 1 | H34: =G34*AH33 -> 197.01 | I34: =H34*F34 -> 4.428 | J34: =H34*Dividend_Yield_pa*Period_Length_Yrs -> 1.477575 | K34: =G34*V33*E34*Period_Length_Yrs -> 1.6242514 | L34: =I34+J34-K34 -> 4.2813236 | M34: =H34*(1+F34) -> 201.438 | N34: =G34*(V33+K34-J34) -> 81.359248 | O34: =M34-N34 -> 120.07875 | P34: =D34*M34 -> 60.4314 | Q34: =MAX(0,P34-O34) -> 0 | R34: =MIN(Q34,W33) -> 0 | S34: =Q34-R34 -> 0 | T34: =IF(S34>0,Liquidation_Slippage*AG34,0) -> 0 | U34: =IF(G34=0,U33,IF(S34>0,MAX(0,O34+R34-T34),O34+R34)) -> 120.07875 | V34: =IF(G34=0,0,IF(S34>0,IF(AG34<M34,N34-R34-AG34*(1-Liquidation_Slippage),0),N34-R34)) -> 81.359248 | W34: =W33-R34 -> 10 | X34: =IF(AND(G34=1,OR(S34=0,AG34<M34)),1,0) -> 1 | Y34: =IF(G34=0,"Liquidated earlier",IF(AF34=1,"DEFAULT - forced liquidation",IF(AI34=1,"Shares sold to meet call",IF(Q34>0,"Margin call met from reserve","OK")))) -> OK | Z34: =U34+W34 -> 130.07875 | AA34: =AA33*(1+F34) -> 201.438 | AB34: =AB33*(1+E34*Period_Length_Yrs)-AA33*Dividend_Yield_pa*Period_Length_Yrs -> 81.359248 | AC34: =AA34-AB34+Liquidity_Reserve_0 -> 130.07875 | AD34: =MAX(AD33,Z34) -> 130.07875 | AE34: =Z34/AD34-1 -> 0 | AF34: =IF(AND(S34>0,AG34>=M34),1,0) -> 0 | AG34: =IF(S34>0,IF(AND(Sell_To_Fund=1,D34>Liquidation_Slippage),MIN(M34,S34/(D34-Liquidation_Slippage)),M34),0) -> 0 | AH34: =IF(G34=0,0,IF(S34>0,IF(AG34<M34,M34-AG34,0),M34)) -> 201.438 | AI34: =IF(AND(S34>0,AG34<M34),1,0) -> 0
A35: 8 | B35: =Period_Unit&" "&A35 -> Quarter 8 | C35: 111.68 | D35: 0.3 | E35: 0.08 | F35: =C35/C34-1 -> -0.0020552229 | G35: =X34 -> 1 | H35: =G35*AH34 -> 201.438 | I35: =H35*F35 -> -0.414 | J35: =H35*Dividend_Yield_pa*Period_Length_Yrs -> 1.510785 | K35: =G35*V34*E35*Period_Length_Yrs -> 1.627185 | L35: =I35+J35-K35 -> -0.53039995 | M35: =H35*(1+F35) -> 201.024 | N35: =G35*(V34+K35-J35) -> 81.475647 | O35: =M35-N35 -> 119.54835 | P35: =D35*M35 -> 60.3072 | Q35: =MAX(0,P35-O35) -> 0 | R35: =MIN(Q35,W34) -> 0 | S35: =Q35-R35 -> 0 | T35: =IF(S35>0,Liquidation_Slippage*AG35,0) -> 0 | U35: =IF(G35=0,U34,IF(S35>0,MAX(0,O35+R35-T35),O35+R35)) -> 119.54835 | V35: =IF(G35=0,0,IF(S35>0,IF(AG35<M35,N35-R35-AG35*(1-Liquidation_Slippage),0),N35-R35)) -> 81.475647 | W35: =W34-R35 -> 10 | X35: =IF(AND(G35=1,OR(S35=0,AG35<M35)),1,0) -> 1 | Y35: =IF(G35=0,"Liquidated earlier",IF(AF35=1,"DEFAULT - forced liquidation",IF(AI35=1,"Shares sold to meet call",IF(Q35>0,"Margin call met from reserve","OK")))) -> OK | Z35: =U35+W35 -> 129.54835 | AA35: =AA34*(1+F35) -> 201.024 | AB35: =AB34*(1+E35*Period_Length_Yrs)-AA34*Dividend_Yield_pa*Period_Length_Yrs -> 81.475647 | AC35: =AA35-AB35+Liquidity_Reserve_0 -> 129.54835 | AD35: =MAX(AD34,Z35) -> 130.07875 | AE35: =Z35/AD35-1 -> -0.0040775295 | AF35: =IF(AND(S35>0,AG35>=M35),1,0) -> 0 | AG35: =IF(S35>0,IF(AND(Sell_To_Fund=1,D35>Liquidation_Slippage),MIN(M35,S35/(D35-Liquidation_Slippage)),M35),0) -> 0 | AH35: =IF(G35=0,0,IF(S35>0,IF(AG35<M35,M35-AG35,0),M35)) -> 201.024 | AI35: =IF(AND(S35>0,AG35<M35),1,0) -> 0
A36: 9 | B36: =Period_Unit&" "&A36 -> Quarter 9 | C36: 116.71 | D36: 0.3 | E36: 0.08 | F36: =C36/C35-1 -> 0.045039398 | G36: =X35 -> 1 | H36: =G36*AH35 -> 201.024 | I36: =H36*F36 -> 9.054 | J36: =H36*Dividend_Yield_pa*Period_Length_Yrs -> 1.50768 | K36: =G36*V35*E36*Period_Length_Yrs -> 1.6295129 | L36: =I36+J36-K36 -> 8.9321671 | M36: =H36*(1+F36) -> 210.078 | N36: =G36*(V35+K36-J36) -> 81.59748 | O36: =M36-N36 -> 128.48052 | P36: =D36*M36 -> 63.0234 | Q36: =MAX(0,P36-O36) -> 0 | R36: =MIN(Q36,W35) -> 0 | S36: =Q36-R36 -> 0 | T36: =IF(S36>0,Liquidation_Slippage*AG36,0) -> 0 | U36: =IF(G36=0,U35,IF(S36>0,MAX(0,O36+R36-T36),O36+R36)) -> 128.48052 | V36: =IF(G36=0,0,IF(S36>0,IF(AG36<M36,N36-R36-AG36*(1-Liquidation_Slippage),0),N36-R36)) -> 81.59748 | W36: =W35-R36 -> 10 | X36: =IF(AND(G36=1,OR(S36=0,AG36<M36)),1,0) -> 1 | Y36: =IF(G36=0,"Liquidated earlier",IF(AF36=1,"DEFAULT - forced liquidation",IF(AI36=1,"Shares sold to meet call",IF(Q36>0,"Margin call met from reserve","OK")))) -> OK | Z36: =U36+W36 -> 138.48052 | AA36: =AA35*(1+F36) -> 210.078 | AB36: =AB35*(1+E36*Period_Length_Yrs)-AA35*Dividend_Yield_pa*Period_Length_Yrs -> 81.59748 | AC36: =AA36-AB36+Liquidity_Reserve_0 -> 138.48052 | AD36: =MAX(AD35,Z36) -> 138.48052 | AE36: =Z36/AD36-1 -> 0 | AF36: =IF(AND(S36>0,AG36>=M36),1,0) -> 0 | AG36: =IF(S36>0,IF(AND(Sell_To_Fund=1,D36>Liquidation_Slippage),MIN(M36,S36/(D36-Liquidation_Slippage)),M36),0) -> 0 | AH36: =IF(G36=0,0,IF(S36>0,IF(AG36<M36,M36-AG36,0),M36)) -> 210.078 | AI36: =IF(AND(S36>0,AG36<M36),1,0) -> 0
A37: 10 | B37: =Period_Unit&" "&A37 -> Quarter 10 | C37: 116.68 | D37: 0.3 | E37: 0.08 | F37: =C37/C36-1 -> -0.00025704738 | G37: =X36 -> 1 | H37: =G37*AH36 -> 210.078 | I37: =H37*F37 -> -0.054 | J37: =H37*Dividend_Yield_pa*Period_Length_Yrs -> 1.575585 | K37: =G37*V36*E37*Period_Length_Yrs -> 1.6319496 | L37: =I37+J37-K37 -> -0.11036461 | M37: =H37*(1+F37) -> 210.024 | N37: =G37*(V36+K37-J37) -> 81.653845 | O37: =M37-N37 -> 128.37015 | P37: =D37*M37 -> 63.0072 | Q37: =MAX(0,P37-O37) -> 0 | R37: =MIN(Q37,W36) -> 0 | S37: =Q37-R37 -> 0 | T37: =IF(S37>0,Liquidation_Slippage*AG37,0) -> 0 | U37: =IF(G37=0,U36,IF(S37>0,MAX(0,O37+R37-T37),O37+R37)) -> 128.37015 | V37: =IF(G37=0,0,IF(S37>0,IF(AG37<M37,N37-R37-AG37*(1-Liquidation_Slippage),0),N37-R37)) -> 81.653845 | W37: =W36-R37 -> 10 | X37: =IF(AND(G37=1,OR(S37=0,AG37<M37)),1,0) -> 1 | Y37: =IF(G37=0,"Liquidated earlier",IF(AF37=1,"DEFAULT - forced liquidation",IF(AI37=1,"Shares sold to meet call",IF(Q37>0,"Margin call met from reserve","OK")))) -> OK | Z37: =U37+W37 -> 138.37015 | AA37: =AA36*(1+F37) -> 210.024 | AB37: =AB36*(1+E37*Period_Length_Yrs)-AA36*Dividend_Yield_pa*Period_Length_Yrs -> 81.653845 | AC37: =AA37-AB37+Liquidity_Reserve_0 -> 138.37015 | AD37: =MAX(AD36,Z37) -> 138.48052 | AE37: =Z37/AD37-1 -> -0.00079696848 | AF37: =IF(AND(S37>0,AG37>=M37),1,0) -> 0 | AG37: =IF(S37>0,IF(AND(Sell_To_Fund=1,D37>Liquidation_Slippage),MIN(M37,S37/(D37-Liquidation_Slippage)),M37),0) -> 0 | AH37: =IF(G37=0,0,IF(S37>0,IF(AG37<M37,M37-AG37,0),M37)) -> 210.024 | AI37: =IF(AND(S37>0,AG37<M37),1,0) -> 0
A38: 11 | B38: =Period_Unit&" "&A38 -> Quarter 11 | C38: 119.16 | D38: 0.3 | E38: 0.08 | F38: =C38/C37-1 -> 0.021254714 | G38: =X37 -> 1 | H38: =G38*AH37 -> 210.024 | I38: =H38*F38 -> 4.464 | J38: =H38*Dividend_Yield_pa*Period_Length_Yrs -> 1.57518 | K38: =G38*V37*E38*Period_Length_Yrs -> 1.6330769 | L38: =I38+J38-K38 -> 4.4061031 | M38: =H38*(1+F38) -> 214.488 | N38: =G38*(V37+K38-J38) -> 81.711742 | O38: =M38-N38 -> 132.77626 | P38: =D38*M38 -> 64.3464 | Q38: =MAX(0,P38-O38) -> 0 | R38: =MIN(Q38,W37) -> 0 | S38: =Q38-R38 -> 0 | T38: =IF(S38>0,Liquidation_Slippage*AG38,0) -> 0 | U38: =IF(G38=0,U37,IF(S38>0,MAX(0,O38+R38-T38),O38+R38)) -> 132.77626 | V38: =IF(G38=0,0,IF(S38>0,IF(AG38<M38,N38-R38-AG38*(1-Liquidation_Slippage),0),N38-R38)) -> 81.711742 | W38: =W37-R38 -> 10 | X38: =IF(AND(G38=1,OR(S38=0,AG38<M38)),1,0) -> 1 | Y38: =IF(G38=0,"Liquidated earlier",IF(AF38=1,"DEFAULT - forced liquidation",IF(AI38=1,"Shares sold to meet call",IF(Q38>0,"Margin call met from reserve","OK")))) -> OK | Z38: =U38+W38 -> 142.77626 | AA38: =AA37*(1+F38) -> 214.488 | AB38: =AB37*(1+E38*Period_Length_Yrs)-AA37*Dividend_Yield_pa*Period_Length_Yrs -> 81.711742 | AC38: =AA38-AB38+Liquidity_Reserve_0 -> 142.77626 | AD38: =MAX(AD37,Z38) -> 142.77626 | AE38: =Z38/AD38-1 -> 0 | AF38: =IF(AND(S38>0,AG38>=M38),1,0) -> 0 | AG38: =IF(S38>0,IF(AND(Sell_To_Fund=1,D38>Liquidation_Slippage),MIN(M38,S38/(D38-Liquidation_Slippage)),M38),0) -> 0 | AH38: =IF(G38=0,0,IF(S38>0,IF(AG38<M38,M38-AG38,0),M38)) -> 214.488 | AI38: =IF(AND(S38>0,AG38<M38),1,0) -> 0
A39: 12 | B39: =Period_Unit&" "&A39 -> Quarter 12 | C39: 120.04 | D39: 0.3 | E39: 0.08 | F39: =C39/C38-1 -> 0.0073850285 | G39: =X38 -> 1 | H39: =G39*AH38 -> 214.488 | I39: =H39*F39 -> 1.584 | J39: =H39*Dividend_Yield_pa*Period_Length_Yrs -> 1.60866 | K39: =G39*V38*E39*Period_Length_Yrs -> 1.6342348 | L39: =I39+J39-K39 -> 1.5584252 | M39: =H39*(1+F39) -> 216.072 | N39: =G39*(V38+K39-J39) -> 81.737317 | O39: =M39-N39 -> 134.33468 | P39: =D39*M39 -> 64.8216 | Q39: =MAX(0,P39-O39) -> 0 | R39: =MIN(Q39,W38) -> 0 | S39: =Q39-R39 -> 0 | T39: =IF(S39>0,Liquidation_Slippage*AG39,0) -> 0 | U39: =IF(G39=0,U38,IF(S39>0,MAX(0,O39+R39-T39),O39+R39)) -> 134.33468 | V39: =IF(G39=0,0,IF(S39>0,IF(AG39<M39,N39-R39-AG39*(1-Liquidation_Slippage),0),N39-R39)) -> 81.737317 | W39: =W38-R39 -> 10 | X39: =IF(AND(G39=1,OR(S39=0,AG39<M39)),1,0) -> 1 | Y39: =IF(G39=0,"Liquidated earlier",IF(AF39=1,"DEFAULT - forced liquidation",IF(AI39=1,"Shares sold to meet call",IF(Q39>0,"Margin call met from reserve","OK")))) -> OK | Z39: =U39+W39 -> 144.33468 | AA39: =AA38*(1+F39) -> 216.072 | AB39: =AB38*(1+E39*Period_Length_Yrs)-AA38*Dividend_Yield_pa*Period_Length_Yrs -> 81.737317 | AC39: =AA39-AB39+Liquidity_Reserve_0 -> 144.33468 | AD39: =MAX(AD38,Z39) -> 144.33468 | AE39: =Z39/AD39-1 -> 0 | AF39: =IF(AND(S39>0,AG39>=M39),1,0) -> 0 | AG39: =IF(S39>0,IF(AND(Sell_To_Fund=1,D39>Liquidation_Slippage),MIN(M39,S39/(D39-Liquidation_Slippage)),M39),0) -> 0 | AH39: =IF(G39=0,0,IF(S39>0,IF(AG39<M39,M39-AG39,0),M39)) -> 216.072 | AI39: =IF(AND(S39>0,AG39<M39),1,0) -> 0
... A59: 32 | B59: =Period_Unit&" "&A59 -> Quarter 32 | C59: 165 | D59: 0.3 | E59: 0.08 | F59: =C59/C58-1 -> 0.015697138 | G59: =X58 -> 1 | H59: =G59*AH58 -> 292.41 | I59: =H59*F59 -> 4.59 | J59: =H59*Dividend_Yield_pa*Period_Length_Yrs -> 2.193075 | K59: =G59*V58*E59*Period_Length_Yrs -> 1.5305908 | L59: =I59+J59-K59 -> 5.2524842 | M59: =H59*(1+F59) -> 297 | N59: =G59*(V58+K59-J59) -> 75.867056 | O59: =M59-N59 -> 221.13294 | P59: =D59*M59 -> 89.1 | Q59: =MAX(0,P59-O59) -> 0 | R59: =MIN(Q59,W58) -> 0 | S59: =Q59-R59 -> 0 | T59: =IF(S59>0,Liquidation_Slippage*AG59,0) -> 0 | U59: =IF(G59=0,U58,IF(S59>0,MAX(0,O59+R59-T59),O59+R59)) -> 221.13294 | V59: =IF(G59=0,0,IF(S59>0,IF(AG59<M59,N59-R59-AG59*(1-Liquidation_Slippage),0),N59-R59)) -> 75.867056 | W59: =W58-R59 -> 10 | X59: =IF(AND(G59=1,OR(S59=0,AG59<M59)),1,0) -> 1 | Y59: =IF(G59=0,"Liquidated earlier",IF(AF59=1,"DEFAULT - forced liquidation",IF(AI59=1,"Shares sold to meet call",IF(Q59>0,"Margin call met from reserve","OK")))) -> OK | Z59: =U59+W59 -> 231.13294 | AA59: =AA58*(1+F59) -> 297 | AB59: =AB58*(1+E59*Period_Length_Yrs)-AA58*Dividend_Yield_pa*Period_Length_Yrs -> 75.867056 | AC59: =AA59-AB59+Liquidity_Reserve_0 -> 231.13294 | AD59: =MAX(AD58,Z59) -> 231.13294 | AE59: =Z59/AD59-1 -> 0 | AF59: =IF(AND(S59>0,AG59>=M59),1,0) -> 0 | AG59: =IF(S59>0,IF(AND(Sell_To_Fund=1,D59>Liquidation_Slippage),MIN(M59,S59/(D59-Liquidation_Slippage)),M59),0) -> 0 | AH59: =IF(G59=0,0,IF(S59>0,IF(AG59<M59,M59-AG59,0),M59)) -> 297 | AI59: =IF(AND(S59>0,AG59<M59),1,0) -> 0

Sheet Case2A_Ruin_ConstRates
A1: Rick Guerin margin trade (plain vanilla) - Case 2A - Ruin with constant margin and financing rates
A2: Same structure on every case sheet; only the blue driver, margin-rate and loan-rate paths differ. P&L = position value x % change in the driver. $mm unless stated.
A3: A 1973-74 style bear market halves the stock market within eight quarters, then recovers to the same end point as Case 1. The broker's maintenance margin rate (30%) and the interest rate on the loan (8%) never change. Even so, falling prices alone push equity below the requirement, the margin calls exceed the small cash reserve, and the investor is sold out near the bottom.
A4: Sell shares to fund an unmet call? 1 = yes, 0 = no (full liquidation) | D4: 0
A5: Key results
A6: Starting capital (equity + reserve) | D6: =Starting_Equity+Liquidity_Reserve_0 -> 110
A7: Ending net worth | D7: =Z59 -> 13.967567
A8: Total return | D8: =D7/D6-1 -> -0.87302212
A9: Maximum drawdown of net worth | D9: =MIN(AE27:AE59) -> -0.87302212
A10: Number of margin calls | D10: =COUNTIF(Q28:Q59,">0") -> 1
A11: Total cash posted to margin | D11: =SUM(R28:R59) -> 10
A12: Lowest liquidity reserve | D12: =MIN(W27:W59) -> 0
A13: First default period | D13: =IFERROR(INDEX(A27:A59,MATCH(1,AF27:AF59,0)),"None") -> 6
A14: Outcome | D14: =IF(ISNUMBER(D13),"RUIN: forced out, "&LOWER(Period_Unit)&" "&D13,IF(D21>0,"SURVIVED: "&D21&" partial sale"&IF(D21>1,"s",""),"SURVIVED to convergence")) -> RUIN: forced out, quarter 6
A15: Peak margin rate | D15: =MAX(D27:D59) -> 0.3
A16: Peak loan interest rate | D16: =MAX(E27:E59) -> 0.08
A17: Net worth if never forced out (shadow) | D17: =AC59 -> 211.65892
A18: Shadow return | D18: =D17/D6-1 -> 0.92417202
A19: Thesis eventually proven right? | D19: =IF(D17>D6,IF(ISNUMBER(D13),"Yes - but only after forced exit","Yes"),"No") -> Yes - but only after forced exit
A20: Value lost to forced liquidation | D20: =D17-D7 -> 197.69136
A21: Partial sales (count) | D21: =SUM(AI28:AI59) -> 0
A22: Shares sold to meet calls ($mm) | D22: =SUM(AG28:AG59) -> 102.042
A23: Liquidation cost paid ($mm) | D23: =SUM(T28:T59) -> 15.3063
A25: Period-by-period simulation
A26: t | B26: Period | C26: Driver (index) | D26: Margin rate (% of position) | E26: Loan interest rate p.a. | F26: % change in driver | G26: Position live at start (1/0) | H26: Exposure: position value at start | I26: Price P&L = exposure x % change | J26: Dividends | K26: Loan interest | L26: Net P&L | M26: Position value at end | N26: Loan before call | O26: Equity before call | P26: Required margin | Q26: Margin call | R26: Cash paid from reserve | S26: Shortfall (unmet call) | T26: Forced-liquidation cost | U26: Equity after call | V26: Loan after call | W26: Liquidity reserve | X26: Position live at end (1/0) | Y26: Status | Z26: Net worth (equity + reserve) | AA26: Shadow position value | AB26: Shadow loan | AC26: Shadow net worth (never forced out) | AD26: Running peak of net worth | AE26: Drawdown | AF26: Default flag | AG26: Shares sold to meet call ($mm of position) | AH26: Position value after call (carried forward) | AI26: Partial-sale flag
A27: 0 | B27: =Period_Unit&" "&A27 -> Quarter 0 | C27: =Entry_Driver -> 100 | D27: =Initial_Margin_Rate -> 0.3 | E27: =Entry_Financing_Rate -> 0.08 | G27: 1 | M27: =Initial_Position_Value -> 180 | U27: =Starting_Equity -> 100 | V27: =Initial_Loan -> 80 | W27: =Liquidity_Reserve_0 -> 10 | X27: 1 | Y27: Position opened | Z27: =U27+W27 -> 110 | AA27: =Initial_Position_Value -> 180 | AB27: =Initial_Loan -> 80 | AC27: =AA27-AB27+Liquidity_Reserve_0 -> 110 | AD27: =Z27 -> 110 | AE27: 0 | AF27: 0 | AG27: 0 | AH27: =Initial_Position_Value -> 180 | AI27: 0
A28: 1 | B28: =Period_Unit&" "&A28 -> Quarter 1 | C28: 99.17 | D28: 0.3 | E28: 0.08 | F28: =C28/C27-1 -> -0.0083 | G28: =X27 -> 1 | H28: =G28*AH27 -> 180 | I28: =H28*F28 -> -1.494 | J28: =H28*Dividend_Yield_pa*Period_Length_Yrs -> 1.35 | K28: =G28*V27*E28*Period_Length_Yrs -> 1.6 | L28: =I28+J28-K28 -> -1.744 | M28: =H28*(1+F28) -> 178.506 | N28: =G28*(V27+K28-J28) -> 80.25 | O28: =M28-N28 -> 98.256 | P28: =D28*M28 -> 53.5518 | Q28: =MAX(0,P28-O28) -> 0 | R28: =MIN(Q28,W27) -> 0 | S28: =Q28-R28 -> 0 | T28: =IF(S28>0,Liquidation_Slippage*AG28,0) -> 0 | U28: =IF(G28=0,U27,IF(S28>0,MAX(0,O28+R28-T28),O28+R28)) -> 98.256 | V28: =IF(G28=0,0,IF(S28>0,IF(AG28<M28,N28-R28-AG28*(1-Liquidation_Slippage),0),N28-R28)) -> 80.25 | W28: =W27-R28 -> 10 | X28: =IF(AND(G28=1,OR(S28=0,AG28<M28)),1,0) -> 1 | Y28: =IF(G28=0,"Liquidated earlier",IF(AF28=1,"DEFAULT - forced liquidation",IF(AI28=1,"Shares sold to meet call",IF(Q28>0,"Margin call met from reserve","OK")))) -> OK | Z28: =U28+W28 -> 108.256 | AA28: =AA27*(1+F28) -> 178.506 | AB28: =AB27*(1+E28*Period_Length_Yrs)-AA27*Dividend_Yield_pa*Period_Length_Yrs -> 80.25 | AC28: =AA28-AB28+Liquidity_Reserve_0 -> 108.256 | AD28: =MAX(AD27,Z28) -> 110 | AE28: =Z28/AD28-1 -> -0.015854545 | AF28: =IF(AND(S28>0,AG28>=M28),1,0) -> 0 | AG28: =IF(S28>0,IF(AND(Sell_To_Fund=1,D28>Liquidation_Slippage),MIN(M28,S28/(D28-Liquidation_Slippage)),M28),0) -> 0 | AH28: =IF(G28=0,0,IF(S28>0,IF(AG28<M28,M28-AG28,0),M28)) -> 178.506 | AI28: =IF(AND(S28>0,AG28<M28),1,0) -> 0
A29: 2 | B29: =Period_Unit&" "&A29 -> Quarter 2 | C29: 91.35 | D29: 0.3 | E29: 0.08 | F29: =C29/C28-1 -> -0.078854492 | G29: =X28 -> 1 | H29: =G29*AH28 -> 178.506 | I29: =H29*F29 -> -14.076 | J29: =H29*Dividend_Yield_pa*Period_Length_Yrs -> 1.338795 | K29: =G29*V28*E29*Period_Length_Yrs -> 1.605 | L29: =I29+J29-K29 -> -14.342205 | M29: =H29*(1+F29) -> 164.43 | N29: =G29*(V28+K29-J29) -> 80.516205 | O29: =M29-N29 -> 83.913795 | P29: =D29*M29 -> 49.329 | Q29: =MAX(0,P29-O29) -> 0 | R29: =MIN(Q29,W28) -> 0 | S29: =Q29-R29 -> 0 | T29: =IF(S29>0,Liquidation_Slippage*AG29,0) -> 0 | U29: =IF(G29=0,U28,IF(S29>0,MAX(0,O29+R29-T29),O29+R29)) -> 83.913795 | V29: =IF(G29=0,0,IF(S29>0,IF(AG29<M29,N29-R29-AG29*(1-Liquidation_Slippage),0),N29-R29)) -> 80.516205 | W29: =W28-R29 -> 10 | X29: =IF(AND(G29=1,OR(S29=0,AG29<M29)),1,0) -> 1 | Y29: =IF(G29=0,"Liquidated earlier",IF(AF29=1,"DEFAULT - forced liquidation",IF(AI29=1,"Shares sold to meet call",IF(Q29>0,"Margin call met from reserve","OK")))) -> OK | Z29: =U29+W29 -> 93.913795 | AA29: =AA28*(1+F29) -> 164.43 | AB29: =AB28*(1+E29*Period_Length_Yrs)-AA28*Dividend_Yield_pa*Period_Length_Yrs -> 80.516205 | AC29: =AA29-AB29+Liquidity_Reserve_0 -> 93.913795 | AD29: =MAX(AD28,Z29) -> 110 | AE29: =Z29/AD29-1 -> -0.14623823 | AF29: =IF(AND(S29>0,AG29>=M29),1,0) -> 0 | AG29: =IF(S29>0,IF(AND(Sell_To_Fund=1,D29>Liquidation_Slippage),MIN(M29,S29/(D29-Liquidation_Slippage)),M29),0) -> 0 | AH29: =IF(G29=0,0,IF(S29>0,IF(AG29<M29,M29-AG29,0),M29)) -> 164.43 | AI29: =IF(AND(S29>0,AG29<M29),1,0) -> 0
A30: 3 | B30: =Period_Unit&" "&A30 -> Quarter 3 | C30: 84.02 | D30: 0.3 | E30: 0.08 | F30: =C30/C29-1 -> -0.080240832 | G30: =X29 -> 1 | H30: =G30*AH29 -> 164.43 | I30: =H30*F30 -> -13.194 | J30: =H30*Dividend_Yield_pa*Period_Length_Yrs -> 1.233225 | K30: =G30*V29*E30*Period_Length_Yrs -> 1.6103241 | L30: =I30+J30-K30 -> -13.571099 | M30: =H30*(1+F30) -> 151.236 | N30: =G30*(V29+K30-J30) -> 80.893304 | O30: =M30-N30 -> 70.342696 | P30: =D30*M30 -> 45.3708 | Q30: =MAX(0,P30-O30) -> 0 | R30: =MIN(Q30,W29) -> 0 | S30: =Q30-R30 -> 0 | T30: =IF(S30>0,Liquidation_Slippage*AG30,0) -> 0 | U30: =IF(G30=0,U29,IF(S30>0,MAX(0,O30+R30-T30),O30+R30)) -> 70.342696 | V30: =IF(G30=0,0,IF(S30>0,IF(AG30<M30,N30-R30-AG30*(1-Liquidation_Slippage),0),N30-R30)) -> 80.893304 | W30: =W29-R30 -> 10 | X30: =IF(AND(G30=1,OR(S30=0,AG30<M30)),1,0) -> 1 | Y30: =IF(G30=0,"Liquidated earlier",IF(AF30=1,"DEFAULT - forced liquidation",IF(AI30=1,"Shares sold to meet call",IF(Q30>0,"Margin call met from reserve","OK")))) -> OK | Z30: =U30+W30 -> 80.342696 | AA30: =AA29*(1+F30) -> 151.236 | AB30: =AB29*(1+E30*Period_Length_Yrs)-AA29*Dividend_Yield_pa*Period_Length_Yrs -> 80.893304 | AC30: =AA30-AB30+Liquidity_Reserve_0 -> 80.342696 | AD30: =MAX(AD29,Z30) -> 110 | AE30: =Z30/AD30-1 -> -0.26961186 | AF30: =IF(AND(S30>0,AG30>=M30),1,0) -> 0 | AG30: =IF(S30>0,IF(AND(Sell_To_Fund=1,D30>Liquidation_Slippage),MIN(M30,S30/(D30-Liquidation_Slippage)),M30),0) -> 0 | AH30: =IF(G30=0,0,IF(S30>0,IF(AG30<M30,M30-AG30,0),M30)) -> 151.236 | AI30: =IF(AND(S30>0,AG30<M30),1,0) -> 0
A31: 4 | B31: =Period_Unit&" "&A31 -> Quarter 4 | C31: 73.68 | D31: 0.3 | E31: 0.08 | F31: =C31/C30-1 -> -0.12306594 | G31: =X30 -> 1 | H31: =G31*AH30 -> 151.236 | I31: =H31*F31 -> -18.612 | J31: =H31*Dividend_Yield_pa*Period_Length_Yrs -> 1.13427 | K31: =G31*V30*E31*Period_Length_Yrs -> 1.6178661 | L31: =I31+J31-K31 -> -19.095596 | M31: =H31*(1+F31) -> 132.624 | N31: =G31*(V30+K31-J31) -> 81.3769 | O31: =M31-N31 -> 51.2471 | P31: =D31*M31 -> 39.7872 | Q31: =MAX(0,P31-O31) -> 0 | R31: =MIN(Q31,W30) -> 0 | S31: =Q31-R31 -> 0 | T31: =IF(S31>0,Liquidation_Slippage*AG31,0) -> 0 | U31: =IF(G31=0,U30,IF(S31>0,MAX(0,O31+R31-T31),O31+R31)) -> 51.2471 | V31: =IF(G31=0,0,IF(S31>0,IF(AG31<M31,N31-R31-AG31*(1-Liquidation_Slippage),0),N31-R31)) -> 81.3769 | W31: =W30-R31 -> 10 | X31: =IF(AND(G31=1,OR(S31=0,AG31<M31)),1,0) -> 1 | Y31: =IF(G31=0,"Liquidated earlier",IF(AF31=1,"DEFAULT - forced liquidation",IF(AI31=1,"Shares sold to meet call",IF(Q31>0,"Margin call met from reserve","OK")))) -> OK | Z31: =U31+W31 -> 61.2471 | AA31: =AA30*(1+F31) -> 132.624 | AB31: =AB30*(1+E31*Period_Length_Yrs)-AA30*Dividend_Yield_pa*Period_Length_Yrs -> 81.3769 | AC31: =AA31-AB31+Liquidity_Reserve_0 -> 61.2471 | AD31: =MAX(AD30,Z31) -> 110 | AE31: =Z31/AD31-1 -> -0.44320818 | AF31: =IF(AND(S31>0,AG31>=M31),1,0) -> 0 | AG31: =IF(S31>0,IF(AND(Sell_To_Fund=1,D31>Liquidation_Slippage),MIN(M31,S31/(D31-Liquidation_Slippage)),M31),0) -> 0 | AH31: =IF(G31=0,0,IF(S31>0,IF(AG31<M31,M31-AG31,0),M31)) -> 132.624 | AI31: =IF(AND(S31>0,AG31<M31),1,0) -> 0
A32: 5 | B32: =Period_Unit&" "&A32 -> Quarter 5 | C32: 65.32 | D32: 0.3 | E32: 0.08 | F32: =C32/C31-1 -> -0.11346363 | G32: =X31 -> 1 | H32: =G32*AH31 -> 132.624 | I32: =H32*F32 -> -15.048 | J32: =H32*Dividend_Yield_pa*Period_Length_Yrs -> 0.99468 | K32: =G32*V31*E32*Period_Length_Yrs -> 1.627538 | L32: =I32+J32-K32 -> -15.680858 | M32: =H32*(1+F32) -> 117.576 | N32: =G32*(V31+K32-J32) -> 82.009758 | O32: =M32-N32 -> 35.566242 | P32: =D32*M32 -> 35.2728 | Q32: =MAX(0,P32-O32) -> 0 | R32: =MIN(Q32,W31) -> 0 | S32: =Q32-R32 -> 0 | T32: =IF(S32>0,Liquidation_Slippage*AG32,0) -> 0 | U32: =IF(G32=0,U31,IF(S32>0,MAX(0,O32+R32-T32),O32+R32)) -> 35.566242 | V32: =IF(G32=0,0,IF(S32>0,IF(AG32<M32,N32-R32-AG32*(1-Liquidation_Slippage),0),N32-R32)) -> 82.009758 | W32: =W31-R32 -> 10 | X32: =IF(AND(G32=1,OR(S32=0,AG32<M32)),1,0) -> 1 | Y32: =IF(G32=0,"Liquidated earlier",IF(AF32=1,"DEFAULT - forced liquidation",IF(AI32=1,"Shares sold to meet call",IF(Q32>0,"Margin call met from reserve","OK")))) -> OK | Z32: =U32+W32 -> 45.566242 | AA32: =AA31*(1+F32) -> 117.576 | AB32: =AB31*(1+E32*Period_Length_Yrs)-AA31*Dividend_Yield_pa*Period_Length_Yrs -> 82.009758 | AC32: =AA32-AB32+Liquidity_Reserve_0 -> 45.566242 | AD32: =MAX(AD31,Z32) -> 110 | AE32: =Z32/AD32-1 -> -0.58576144 | AF32: =IF(AND(S32>0,AG32>=M32),1,0) -> 0 | AG32: =IF(S32>0,IF(AND(Sell_To_Fund=1,D32>Liquidation_Slippage),MIN(M32,S32/(D32-Liquidation_Slippage)),M32),0) -> 0 | AH32: =IF(G32=0,0,IF(S32>0,IF(AG32<M32,M32-AG32,0),M32)) -> 117.576 | AI32: =IF(AND(S32>0,AG32<M32),1,0) -> 0
A33: 6 | B33: =Period_Unit&" "&A33 -> Quarter 6 | C33: 56.69 | D33: 0.3 | E33: 0.08 | F33: =C33/C32-1 -> -0.1321188 | G33: =X32 -> 1 | H33: =G33*AH32 -> 117.576 | I33: =H33*F33 -> -15.534 | J33: =H33*Dividend_Yield_pa*Period_Length_Yrs -> 0.88182 | K33: =G33*V32*E33*Period_Length_Yrs -> 1.6401952 | L33: =I33+J33-K33 -> -16.292375 | M33: =H33*(1+F33) -> 102.042 | N33: =G33*(V32+K33-J33) -> 82.768133 | O33: =M33-N33 -> 19.273867 | P33: =D33*M33 -> 30.6126 | Q33: =MAX(0,P33-O33) -> 11.338733 | R33: =MIN(Q33,W32) -> 10 | S33: =Q33-R33 -> 1.3387333 | T33: =IF(S33>0,Liquidation_Slippage*AG33,0) -> 15.3063 | U33: =IF(G33=0,U32,IF(S33>0,MAX(0,O33+R33-T33),O33+R33)) -> 13.967567 | V33: =IF(G33=0,0,IF(S33>0,IF(AG33<M33,N33-R33-AG33*(1-Liquidation_Slippage),0),N33-R33)) -> 0 | W33: =W32-R33 -> 0 | X33: =IF(AND(G33=1,OR(S33=0,AG33<M33)),1,0) -> 0 | Y33: =IF(G33=0,"Liquidated earlier",IF(AF33=1,"DEFAULT - forced liquidation",IF(AI33=1,"Shares sold to meet call",IF(Q33>0,"Margin call met from reserve","OK")))) -> DEFAULT - forced liquidation | Z33: =U33+W33 -> 13.967567 | AA33: =AA32*(1+F33) -> 102.042 | AB33: =AB32*(1+E33*Period_Length_Yrs)-AA32*Dividend_Yield_pa*Period_Length_Yrs -> 82.768133 | AC33: =AA33-AB33+Liquidity_Reserve_0 -> 29.273867 | AD33: =MAX(AD32,Z33) -> 110 | AE33: =Z33/AD33-1 -> -0.87302212 | AF33: =IF(AND(S33>0,AG33>=M33),1,0) -> 1 | AG33: =IF(S33>0,IF(AND(Sell_To_Fund=1,D33>Liquidation_Slippage),MIN(M33,S33/(D33-Liquidation_Slippage)),M33),0) -> 102.042 | AH33: =IF(G33=0,0,IF(S33>0,IF(AG33<M33,M33-AG33,0),M33)) -> 0 | AI33: =IF(AND(S33>0,AG33<M33),1,0) -> 0
A34: 7 | B34: =Period_Unit&" "&A34 -> Quarter 7 | C34: 52.67 | D34: 0.3 | E34: 0.08 | F34: =C34/C33-1 -> -0.070911977 | G34: =X33 -> 0 | H34: =G34*AH33 -> 0 | I34: =H34*F34 -> 0 | J34: =H34*Dividend_Yield_pa*Period_Length_Yrs -> 0 | K34: =G34*V33*E34*Period_Length_Yrs -> 0 | L34: =I34+J34-K34 -> 0 | M34: =H34*(1+F34) -> 0 | N34: =G34*(V33+K34-J34) -> 0 | O34: =M34-N34 -> 0 | P34: =D34*M34 -> 0 | Q34: =MAX(0,P34-O34) -> 0 | R34: =MIN(Q34,W33) -> 0 | S34: =Q34-R34 -> 0 | T34: =IF(S34>0,Liquidation_Slippage*AG34,0) -> 0 | U34: =IF(G34=0,U33,IF(S34>0,MAX(0,O34+R34-T34),O34+R34)) -> 13.967567 | V34: =IF(G34=0,0,IF(S34>0,IF(AG34<M34,N34-R34-AG34*(1-Liquidation_Slippage),0),N34-R34)) -> 0 | W34: =W33-R34 -> 0 | X34: =IF(AND(G34=1,OR(S34=0,AG34<M34)),1,0) -> 0 | Y34: =IF(G34=0,"Liquidated earlier",IF(AF34=1,"DEFAULT - forced liquidation",IF(AI34=1,"Shares sold to meet call",IF(Q34>0,"Margin call met from reserve","OK")))) -> Liquidated earlier | Z34: =U34+W34 -> 13.967567 | AA34: =AA33*(1+F34) -> 94.806 | AB34: =AB33*(1+E34*Period_Length_Yrs)-AA33*Dividend_Yield_pa*Period_Length_Yrs -> 83.658181 | AC34: =AA34-AB34+Liquidity_Reserve_0 -> 21.147819 | AD34: =MAX(AD33,Z34) -> 110 | AE34: =Z34/AD34-1 -> -0.87302212 | AF34: =IF(AND(S34>0,AG34>=M34),1,0) -> 0 | AG34: =IF(S34>0,IF(AND(Sell_To_Fund=1,D34>Liquidation_Slippage),MIN(M34,S34/(D34-Liquidation_Slippage)),M34),0) -> 0 | AH34: =IF(G34=0,0,IF(S34>0,IF(AG34<M34,M34-AG34,0),M34)) -> 0 | AI34: =IF(AND(S34>0,AG34<M34),1,0) -> 0
A35: 8 | B35: =Period_Unit&" "&A35 -> Quarter 8 | C35: 50 | D35: 0.3 | E35: 0.08 | F35: =C35/C34-1 -> -0.050692994 | G35: =X34 -> 0 | H35: =G35*AH34 -> 0 | I35: =H35*F35 -> 0 | J35: =H35*Dividend_Yield_pa*Period_Length_Yrs -> 0 | K35: =G35*V34*E35*Period_Length_Yrs -> 0 | L35: =I35+J35-K35 -> 0 | M35: =H35*(1+F35) -> 0 | N35: =G35*(V34+K35-J35) -> 0 | O35: =M35-N35 -> 0 | P35: =D35*M35 -> 0 | Q35: =MAX(0,P35-O35) -> 0 | R35: =MIN(Q35,W34) -> 0 | S35: =Q35-R35 -> 0 | T35: =IF(S35>0,Liquidation_Slippage*AG35,0) -> 0 | U35: =IF(G35=0,U34,IF(S35>0,MAX(0,O35+R35-T35),O35+R35)) -> 13.967567 | V35: =IF(G35=0,0,IF(S35>0,IF(AG35<M35,N35-R35-AG35*(1-Liquidation_Slippage),0),N35-R35)) -> 0 | W35: =W34-R35 -> 0 | X35: =IF(AND(G35=1,OR(S35=0,AG35<M35)),1,0) -> 0 | Y35: =IF(G35=0,"Liquidated earlier",IF(AF35=1,"DEFAULT - forced liquidation",IF(AI35=1,"Shares sold to meet call",IF(Q35>0,"Margin call met from reserve","OK")))) -> Liquidated earlier | Z35: =U35+W35 -> 13.967567 | AA35: =AA34*(1+F35) -> 90 | AB35: =AB34*(1+E35*Period_Length_Yrs)-AA34*Dividend_Yield_pa*Period_Length_Yrs -> 84.6203 | AC35: =AA35-AB35+Liquidity_Reserve_0 -> 15.3797 | AD35: =MAX(AD34,Z35) -> 110 | AE35: =Z35/AD35-1 -> -0.87302212 | AF35: =IF(AND(S35>0,AG35>=M35),1,0) -> 0 | AG35: =IF(S35>0,IF(AND(Sell_To_Fund=1,D35>Liquidation_Slippage),MIN(M35,S35/(D35-Liquidation_Slippage)),M35),0) -> 0 | AH35: =IF(G35=0,0,IF(S35>0,IF(AG35<M35,M35-AG35,0),M35)) -> 0 | AI35: =IF(AND(S35>0,AG35<M35),1,0) -> 0
A36: 9 | B36: =Period_Unit&" "&A36 -> Quarter 9 | C36: 51.38 | D36: 0.3 | E36: 0.08 | F36: =C36/C35-1 -> 0.0276 | G36: =X35 -> 0 | H36: =G36*AH35 -> 0 | I36: =H36*F36 -> 0 | J36: =H36*Dividend_Yield_pa*Period_Length_Yrs -> 0 | K36: =G36*V35*E36*Period_Length_Yrs -> 0 | L36: =I36+J36-K36 -> 0 | M36: =H36*(1+F36) -> 0 | N36: =G36*(V35+K36-J36) -> 0 | O36: =M36-N36 -> 0 | P36: =D36*M36 -> 0 | Q36: =MAX(0,P36-O36) -> 0 | R36: =MIN(Q36,W35) -> 0 | S36: =Q36-R36 -> 0 | T36: =IF(S36>0,Liquidation_Slippage*AG36,0) -> 0 | U36: =IF(G36=0,U35,IF(S36>0,MAX(0,O36+R36-T36),O36+R36)) -> 13.967567 | V36: =IF(G36=0,0,IF(S36>0,IF(AG36<M36,N36-R36-AG36*(1-Liquidation_Slippage),0),N36-R36)) -> 0 | W36: =W35-R36 -> 0 | X36: =IF(AND(G36=1,OR(S36=0,AG36<M36)),1,0) -> 0 | Y36: =IF(G36=0,"Liquidated earlier",IF(AF36=1,"DEFAULT - forced liquidation",IF(AI36=1,"Shares sold to meet call",IF(Q36>0,"Margin call met from reserve","OK")))) -> Liquidated earlier | Z36: =U36+W36 -> 13.967567 | AA36: =AA35*(1+F36) -> 92.484 | AB36: =AB35*(1+E36*Period_Length_Yrs)-AA35*Dividend_Yield_pa*Period_Length_Yrs -> 85.637706 | AC36: =AA36-AB36+Liquidity_Reserve_0 -> 16.846294 | AD36: =MAX(AD35,Z36) -> 110 | AE36: =Z36/AD36-1 -> -0.87302212 | AF36: =IF(AND(S36>0,AG36>=M36),1,0) -> 0 | AG36: =IF(S36>0,IF(AND(Sell_To_Fund=1,D36>Liquidation_Slippage),MIN(M36,S36/(D36-Liquidation_Slippage)),M36),0) -> 0 | AH36: =IF(G36=0,0,IF(S36>0,IF(AG36<M36,M36-AG36,0),M36)) -> 0 | AI36: =IF(AND(S36>0,AG36<M36),1,0) -> 0
A37: 10 | B37: =Period_Unit&" "&A37 -> Quarter 10 | C37: 52.84 | D37: 0.3 | E37: 0.08 | F37: =C37/C36-1 -> 0.028415726 | G37: =X36 -> 0 | H37: =G37*AH36 -> 0 | I37: =H37*F37 -> 0 | J37: =H37*Dividend_Yield_pa*Period_Length_Yrs -> 0 | K37: =G37*V36*E37*Period_Length_Yrs -> 0 | L37: =I37+J37-K37 -> 0 | M37: =H37*(1+F37) -> 0 | N37: =G37*(V36+K37-J37) -> 0 | O37: =M37-N37 -> 0 | P37: =D37*M37 -> 0 | Q37: =MAX(0,P37-O37) -> 0 | R37: =MIN(Q37,W36) -> 0 | S37: =Q37-R37 -> 0 | T37: =IF(S37>0,Liquidation_Slippage*AG37,0) -> 0 | U37: =IF(G37=0,U36,IF(S37>0,MAX(0,O37+R37-T37),O37+R37)) -> 13.967567 | V37: =IF(G37=0,0,IF(S37>0,IF(AG37<M37,N37-R37-AG37*(1-Liquidation_Slippage),0),N37-R37)) -> 0 | W37: =W36-R37 -> 0 | X37: =IF(AND(G37=1,OR(S37=0,AG37<M37)),1,0) -> 0 | Y37: =IF(G37=0,"Liquidated earlier",IF(AF37=1,"DEFAULT - forced liquidation",IF(AI37=1,"Shares sold to meet call",IF(Q37>0,"Margin call met from reserve","OK")))) -> Liquidated earlier | Z37: =U37+W37 -> 13.967567 | AA37: =AA36*(1+F37) -> 95.112 | AB37: =AB36*(1+E37*Period_Length_Yrs)-AA36*Dividend_Yield_pa*Period_Length_Yrs -> 86.65683 | AC37: =AA37-AB37+Liquidity_Reserve_0 -> 18.45517 | AD37: =MAX(AD36,Z37) -> 110 | AE37: =Z37/AD37-1 -> -0.87302212 | AF37: =IF(AND(S37>0,AG37>=M37),1,0) -> 0 | AG37: =IF(S37>0,IF(AND(Sell_To_Fund=1,D37>Liquidation_Slippage),MIN(M37,S37/(D37-Liquidation_Slippage)),M37),0) -> 0 | AH37: =IF(G37=0,0,IF(S37>0,IF(AG37<M37,M37-AG37,0),M37)) -> 0 | AI37: =IF(AND(S37>0,AG37<M37),1,0) -> 0
A38: 11 | B38: =Period_Unit&" "&A38 -> Quarter 11 | C38: 54.45 | D38: 0.3 | E38: 0.08 | F38: =C38/C37-1 -> 0.030469341 | G38: =X37 -> 0 | H38: =G38*AH37 -> 0 | I38: =H38*F38 -> 0 | J38: =H38*Dividend_Yield_pa*Period_Length_Yrs -> 0 | K38: =G38*V37*E38*Period_Length_Yrs -> 0 | L38: =I38+J38-K38 -> 0 | M38: =H38*(1+F38) -> 0 | N38: =G38*(V37+K38-J38) -> 0 | O38: =M38-N38 -> 0 | P38: =D38*M38 -> 0 | Q38: =MAX(0,P38-O38) -> 0 | R38: =MIN(Q38,W37) -> 0 | S38: =Q38-R38 -> 0 | T38: =IF(S38>0,Liquidation_Slippage*AG38,0) -> 0 | U38: =IF(G38=0,U37,IF(S38>0,MAX(0,O38+R38-T38),O38+R38)) -> 13.967567 | V38: =IF(G38=0,0,IF(S38>0,IF(AG38<M38,N38-R38-AG38*(1-Liquidation_Slippage),0),N38-R38)) -> 0 | W38: =W37-R38 -> 0 | X38: =IF(AND(G38=1,OR(S38=0,AG38<M38)),1,0) -> 0 | Y38: =IF(G38=0,"Liquidated earlier",IF(AF38=1,"DEFAULT - forced liquidation",IF(AI38=1,"Shares sold to meet call",IF(Q38>0,"Margin call met from reserve","OK")))) -> Liquidated earlier | Z38: =U38+W38 -> 13.967567 | AA38: =AA37*(1+F38) -> 98.01 | AB38: =AB37*(1+E38*Period_Length_Yrs)-AA37*Dividend_Yield_pa*Period_Length_Yrs -> 87.676626 | AC38: =AA38-AB38+Liquidity_Reserve_0 -> 20.333374 | AD38: =MAX(AD37,Z38) -> 110 | AE38: =Z38/AD38-1 -> -0.87302212 | AF38: =IF(AND(S38>0,AG38>=M38),1,0) -> 0 | AG38: =IF(S38>0,IF(AND(Sell_To_Fund=1,D38>Liquidation_Slippage),MIN(M38,S38/(D38-Liquidation_Slippage)),M38),0) -> 0 | AH38: =IF(G38=0,0,IF(S38>0,IF(AG38<M38,M38-AG38,0),M38)) -> 0 | AI38: =IF(AND(S38>0,AG38<M38),1,0) -> 0
A39: 12 | B39: =Period_Unit&" "&A39 -> Quarter 12 | C39: 57.14 | D39: 0.3 | E39: 0.08 | F39: =C39/C38-1 -> 0.049403122 | G39: =X38 -> 0 | H39: =G39*AH38 -> 0 | I39: =H39*F39 -> 0 | J39: =H39*Dividend_Yield_pa*Period_Length_Yrs -> 0 | K39: =G39*V38*E39*Period_Length_Yrs -> 0 | L39: =I39+J39-K39 -> 0 | M39: =H39*(1+F39) -> 0 | N39: =G39*(V38+K39-J39) -> 0 | O39: =M39-N39 -> 0 | P39: =D39*M39 -> 0 | Q39: =MAX(0,P39-O39) -> 0 | R39: =MIN(Q39,W38) -> 0 | S39: =Q39-R39 -> 0 | T39: =IF(S39>0,Liquidation_Slippage*AG39,0) -> 0 | U39: =IF(G39=0,U38,IF(S39>0,MAX(0,O39+R39-T39),O39+R39)) -> 13.967567 | V39: =IF(G39=0,0,IF(S39>0,IF(AG39<M39,N39-R39-AG39*(1-Liquidation_Slippage),0),N39-R39)) -> 0 | W39: =W38-R39 -> 0 | X39: =IF(AND(G39=1,OR(S39=0,AG39<M39)),1,0) -> 0 | Y39: =IF(G39=0,"Liquidated earlier",IF(AF39=1,"DEFAULT - forced liquidation",IF(AI39=1,"Shares sold to meet call",IF(Q39>0,"Margin call met from reserve","OK")))) -> Liquidated earlier | Z39: =U39+W39 -> 13.967567 | AA39: =AA38*(1+F39) -> 102.852 | AB39: =AB38*(1+E39*Period_Length_Yrs)-AA38*Dividend_Yield_pa*Period_Length_Yrs -> 88.695084 | AC39: =AA39-AB39+Liquidity_Reserve_0 -> 24.156916 | AD39: =MAX(AD38,Z39) -> 110 | AE39: =Z39/AD39-1 -> -0.87302212 | AF39: =IF(AND(S39>0,AG39>=M39),1,0) -> 0 | AG39: =IF(S39>0,IF(AND(Sell_To_Fund=1,D39>Liquidation_Slippage),MIN(M39,S39/(D39-Liquidation_Slippage)),M39),0) -> 0 | AH39: =IF(G39=0,0,IF(S39>0,IF(AG39<M39,M39-AG39,0),M39)) -> 0 | AI39: =IF(AND(S39>0,AG39<M39),1,0) -> 0
... A59: 32 | B59: =Period_Unit&" "&A59 -> Quarter 32 | C59: 165 | D59: 0.3 | E59: 0.08 | F59: =C59/C58-1 -> -0.011324825 | G59: =X58 -> 0 | H59: =G59*AH58 -> 0 | I59: =H59*F59 -> 0 | J59: =H59*Dividend_Yield_pa*Period_Length_Yrs -> 0 | K59: =G59*V58*E59*Period_Length_Yrs -> 0 | L59: =I59+J59-K59 -> 0 | M59: =H59*(1+F59) -> 0 | N59: =G59*(V58+K59-J59) -> 0 | O59: =M59-N59 -> 0 | P59: =D59*M59 -> 0 | Q59: =MAX(0,P59-O59) -> 0 | R59: =MIN(Q59,W58) -> 0 | S59: =Q59-R59 -> 0 | T59: =IF(S59>0,Liquidation_Slippage*AG59,0) -> 0 | U59: =IF(G59=0,U58,IF(S59>0,MAX(0,O59+R59-T59),O59+R59)) -> 13.967567 | V59: =IF(G59=0,0,IF(S59>0,IF(AG59<M59,N59-R59-AG59*(1-Liquidation_Slippage),0),N59-R59)) -> 0 | W59: =W58-R59 -> 0 | X59: =IF(AND(G59=1,OR(S59=0,AG59<M59)),1,0) -> 0 | Y59: =IF(G59=0,"Liquidated earlier",IF(AF59=1,"DEFAULT - forced liquidation",IF(AI59=1,"Shares sold to meet call",IF(Q59>0,"Margin call met from reserve","OK")))) -> Liquidated earlier | Z59: =U59+W59 -> 13.967567 | AA59: =AA58*(1+F59) -> 297 | AB59: =AB58*(1+E59*Period_Length_Yrs)-AA58*Dividend_Yield_pa*Period_Length_Yrs -> 95.341077 | AC59: =AA59-AB59+Liquidity_Reserve_0 -> 211.65892 | AD59: =MAX(AD58,Z59) -> 110 | AE59: =Z59/AD59-1 -> -0.87302212 | AF59: =IF(AND(S59>0,AG59>=M59),1,0) -> 0 | AG59: =IF(S59>0,IF(AND(Sell_To_Fund=1,D59>Liquidation_Slippage),MIN(M59,S59/(D59-Liquidation_Slippage)),M59),0) -> 0 | AH59: =IF(G59=0,0,IF(S59>0,IF(AG59<M59,M59-AG59,0),M59)) -> 0 | AI59: =IF(AND(S59>0,AG59<M59),1,0) -> 0

Sheet Case2B_Ruin_ChangingRates
A1: Rick Guerin margin trade (plain vanilla) - Case 2B - Ruin with changing margin and financing rates
A2: Same structure on every case sheet; only the blue driver, margin-rate and loan-rate paths differ. P&L = position value x % change in the driver. $mm unless stated.
A3: Three acts. Act 1: prices fall (the P&L turns red), the broker raises the margin rate and the loan rate climbs; two margin calls eat into the reserve. Act 2: a protracted rally turns the P&L around and, with a lag, margin and loan rates ease briefly. Act 3: a second, deeper fall pushes the P&L red again just as margin and loan rates rise to new highs; the remaining reserve cannot fund the call and the investor is liquidated. Prices later recover to the same end point as Case 1.
A4: Sell shares to fund an unmet call? 1 = yes, 0 = no (full liquidation) | D4: 0
A5: Key results
A6: Starting capital (equity + reserve) | D6: =Starting_Equity+Liquidity_Reserve_0 -> 110
A7: Ending net worth | D7: =Z59 -> 26.306903
A8: Total return | D8: =D7/D6-1 -> -0.76084634
A9: Maximum drawdown of net worth | D9: =MIN(AE27:AE59) -> -0.7952881
A10: Number of margin calls | D10: =COUNTIF(Q28:Q59,">0") -> 4
A11: Total cash posted to margin | D11: =SUM(R28:R59) -> 10
A12: Lowest liquidity reserve | D12: =MIN(W27:W59) -> 0
A13: First default period | D13: =IFERROR(INDEX(A27:A59,MATCH(1,AF27:AF59,0)),"None") -> 18
A14: Outcome | D14: =IF(ISNUMBER(D13),"RUIN: forced out, "&LOWER(Period_Unit)&" "&D13,IF(D21>0,"SURVIVED: "&D21&" partial sale"&IF(D21>1,"s",""),"SURVIVED to convergence")) -> RUIN: forced out, quarter 18
A15: Peak margin rate | D15: =MAX(D27:D59) -> 0.6
A16: Peak loan interest rate | D16: =MAX(E27:E59) -> 0.13
A17: Net worth if never forced out (shadow) | D17: =AC59 -> 186.23057
A18: Shadow return | D18: =D17/D6-1 -> 0.69300514
A19: Thesis eventually proven right? | D19: =IF(D17>D6,IF(ISNUMBER(D13),"Yes - but only after forced exit","Yes"),"No") -> Yes - but only after forced exit
A20: Value lost to forced liquidation | D20: =D17-D7 -> 159.92366
A21: Partial sales (count) | D21: =SUM(AI28:AI59) -> 0
A22: Shares sold to meet calls ($mm) | D22: =SUM(AG28:AG59) -> 127.422
A23: Liquidation cost paid ($mm) | D23: =SUM(T28:T59) -> 19.1133
A25: Period-by-period simulation
A26: t | B26: Period | C26: Driver (index) | D26: Margin rate (% of position) | E26: Loan interest rate p.a. | F26: % change in driver | G26: Position live at start (1/0) | H26: Exposure: position value at start | I26: Price P&L = exposure x % change | J26: Dividends | K26: Loan interest | L26: Net P&L | M26: Position value at end | N26: Loan before call | O26: Equity before call | P26: Required margin | Q26: Margin call | R26: Cash paid from reserve | S26: Shortfall (unmet call) | T26: Forced-liquidation cost | U26: Equity after call | V26: Loan after call | W26: Liquidity reserve | X26: Position live at end (1/0) | Y26: Status | Z26: Net worth (equity + reserve) | AA26: Shadow position value | AB26: Shadow loan | AC26: Shadow net worth (never forced out) | AD26: Running peak of net worth | AE26: Drawdown | AF26: Default flag | AG26: Shares sold to meet call ($mm of position) | AH26: Position value after call (carried forward) | AI26: Partial-sale flag
A27: 0 | B27: =Period_Unit&" "&A27 -> Quarter 0 | C27: =Entry_Driver -> 100 | D27: =Initial_Margin_Rate -> 0.3 | E27: =Entry_Financing_Rate -> 0.08 | G27: 1 | M27: =Initial_Position_Value -> 180 | U27: =Starting_Equity -> 100 | V27: =Initial_Loan -> 80 | W27: =Liquidity_Reserve_0 -> 10 | X27: 1 | Y27: Position opened | Z27: =U27+W27 -> 110 | AA27: =Initial_Position_Value -> 180 | AB27: =Initial_Loan -> 80 | AC27: =AA27-AB27+Liquidity_Reserve_0 -> 110 | AD27: =Z27 -> 110 | AE27: 0 | AF27: 0 | AG27: 0 | AH27: =Initial_Position_Value -> 180 | AI27: 0
A28: 1 | B28: =Period_Unit&" "&A28 -> Quarter 1 | C28: 96.63 | D28: 0.33 | E28: 0.085 | F28: =C28/C27-1 -> -0.0337 | G28: =X27 -> 1 | H28: =G28*AH27 -> 180 | I28: =H28*F28 -> -6.066 | J28: =H28*Dividend_Yield_pa*Period_Length_Yrs -> 1.35 | K28: =G28*V27*E28*Period_Length_Yrs -> 1.7 | L28: =I28+J28-K28 -> -6.416 | M28: =H28*(1+F28) -> 173.934 | N28: =G28*(V27+K28-J28) -> 80.35 | O28: =M28-N28 -> 93.584 | P28: =D28*M28 -> 57.39822 | Q28: =MAX(0,P28-O28) -> 0 | R28: =MIN(Q28,W27) -> 0 | S28: =Q28-R28 -> 0 | T28: =IF(S28>0,Liquidation_Slippage*AG28,0) -> 0 | U28: =IF(G28=0,U27,IF(S28>0,MAX(0,O28+R28-T28),O28+R28)) -> 93.584 | V28: =IF(G28=0,0,IF(S28>0,IF(AG28<M28,N28-R28-AG28*(1-Liquidation_Slippage),0),N28-R28)) -> 80.35 | W28: =W27-R28 -> 10 | X28: =IF(AND(G28=1,OR(S28=0,AG28<M28)),1,0) -> 1 | Y28: =IF(G28=0,"Liquidated earlier",IF(AF28=1,"DEFAULT - forced liquidation",IF(AI28=1,"Shares sold to meet call",IF(Q28>0,"Margin call met from reserve","OK")))) -> OK | Z28: =U28+W28 -> 103.584 | AA28: =AA27*(1+F28) -> 173.934 | AB28: =AB27*(1+E28*Period_Length_Yrs)-AA27*Dividend_Yield_pa*Period_Length_Yrs -> 80.35 | AC28: =AA28-AB28+Liquidity_Reserve_0 -> 103.584 | AD28: =MAX(AD27,Z28) -> 110 | AE28: =Z28/AD28-1 -> -0.058327273 | AF28: =IF(AND(S28>0,AG28>=M28),1,0) -> 0 | AG28: =IF(S28>0,IF(AND(Sell_To_Fund=1,D28>Liquidation_Slippage),MIN(M28,S28/(D28-Liquidation_Slippage)),M28),0) -> 0 | AH28: =IF(G28=0,0,IF(S28>0,IF(AG28<M28,M28-AG28,0),M28)) -> 173.934 | AI28: =IF(AND(S28>0,AG28<M28),1,0) -> 0
A29: 2 | B29: =Period_Unit&" "&A29 -> Quarter 2 | C29: 91.52 | D29: 0.36 | E29: 0.09 | F29: =C29/C28-1 -> -0.052882128 | G29: =X28 -> 1 | H29: =G29*AH28 -> 173.934 | I29: =H29*F29 -> -9.198 | J29: =H29*Dividend_Yield_pa*Period_Length_Yrs -> 1.304505 | K29: =G29*V28*E29*Period_Length_Yrs -> 1.807875 | L29: =I29+J29-K29 -> -9.70137 | M29: =H29*(1+F29) -> 164.736 | N29: =G29*(V28+K29-J29) -> 80.85337 | O29: =M29-N29 -> 83.88263 | P29: =D29*M29 -> 59.30496 | Q29: =MAX(0,P29-O29) -> 0 | R29: =MIN(Q29,W28) -> 0 | S29: =Q29-R29 -> 0 | T29: =IF(S29>0,Liquidation_Slippage*AG29,0) -> 0 | U29: =IF(G29=0,U28,IF(S29>0,MAX(0,O29+R29-T29),O29+R29)) -> 83.88263 | V29: =IF(G29=0,0,IF(S29>0,IF(AG29<M29,N29-R29-AG29*(1-Liquidation_Slippage),0),N29-R29)) -> 80.85337 | W29: =W28-R29 -> 10 | X29: =IF(AND(G29=1,OR(S29=0,AG29<M29)),1,0) -> 1 | Y29: =IF(G29=0,"Liquidated earlier",IF(AF29=1,"DEFAULT - forced liquidation",IF(AI29=1,"Shares sold to meet call",IF(Q29>0,"Margin call met from reserve","OK")))) -> OK | Z29: =U29+W29 -> 93.88263 | AA29: =AA28*(1+F29) -> 164.736 | AB29: =AB28*(1+E29*Period_Length_Yrs)-AA28*Dividend_Yield_pa*Period_Length_Yrs -> 80.85337 | AC29: =AA29-AB29+Liquidity_Reserve_0 -> 93.88263 | AD29: =MAX(AD28,Z29) -> 110 | AE29: =Z29/AD29-1 -> -0.14652155 | AF29: =IF(AND(S29>0,AG29>=M29),1,0) -> 0 | AG29: =IF(S29>0,IF(AND(Sell_To_Fund=1,D29>Liquidation_Slippage),MIN(M29,S29/(D29-Liquidation_Slippage)),M29),0) -> 0 | AH29: =IF(G29=0,0,IF(S29>0,IF(AG29<M29,M29-AG29,0),M29)) -> 164.736 | AI29: =IF(AND(S29>0,AG29<M29),1,0) -> 0
A30: 3 | B30: =Period_Unit&" "&A30 -> Quarter 3 | C30: 87.39 | D30: 0.3688 | E30: 0.0915 | F30: =C30/C29-1 -> -0.045126748 | G30: =X29 -> 1 | H30: =G30*AH29 -> 164.736 | I30: =H30*F30 -> -7.434 | J30: =H30*Dividend_Yield_pa*Period_Length_Yrs -> 1.23552 | K30: =G30*V29*E30*Period_Length_Yrs -> 1.8495208 | L30: =I30+J30-K30 -> -8.0480008 | M30: =H30*(1+F30) -> 157.302 | N30: =G30*(V29+K30-J30) -> 81.467371 | O30: =M30-N30 -> 75.834629 | P30: =D30*M30 -> 58.012978 | Q30: =MAX(0,P30-O30) -> 0 | R30: =MIN(Q30,W29) -> 0 | S30: =Q30-R30 -> 0 | T30: =IF(S30>0,Liquidation_Slippage*AG30,0) -> 0 | U30: =IF(G30=0,U29,IF(S30>0,MAX(0,O30+R30-T30),O30+R30)) -> 75.834629 | V30: =IF(G30=0,0,IF(S30>0,IF(AG30<M30,N30-R30-AG30*(1-Liquidation_Slippage),0),N30-R30)) -> 81.467371 | W30: =W29-R30 -> 10 | X30: =IF(AND(G30=1,OR(S30=0,AG30<M30)),1,0) -> 1 | Y30: =IF(G30=0,"Liquidated earlier",IF(AF30=1,"DEFAULT - forced liquidation",IF(AI30=1,"Shares sold to meet call",IF(Q30>0,"Margin call met from reserve","OK")))) -> OK | Z30: =U30+W30 -> 85.834629 | AA30: =AA29*(1+F30) -> 157.302 | AB30: =AB29*(1+E30*Period_Length_Yrs)-AA29*Dividend_Yield_pa*Period_Length_Yrs -> 81.467371 | AC30: =AA30-AB30+Liquidity_Reserve_0 -> 85.834629 | AD30: =MAX(AD29,Z30) -> 110 | AE30: =Z30/AD30-1 -> -0.21968519 | AF30: =IF(AND(S30>0,AG30>=M30),1,0) -> 0 | AG30: =IF(S30>0,IF(AND(Sell_To_Fund=1,D30>Liquidation_Slippage),MIN(M30,S30/(D30-Liquidation_Slippage)),M30),0) -> 0 | AH30: =IF(G30=0,0,IF(S30>0,IF(AG30<M30,M30-AG30,0),M30)) -> 157.302 | AI30: =IF(AND(S30>0,AG30<M30),1,0) -> 0
