Workbook

Sheet README
B1: The Yen Carry Trade and the August 2024 Unwind
B2: A teaching model for MBA students. Latticework for Investment Management, IIM Mumbai.
B5: What this workbook does
B6: 1. Builds a single yen carry trade step by step: borrow JPY at ~0%, convert to USD, earn ~5.3% in T-bills, repay the yen later.
B7: 2. Splits the P&L into CARRY (the rate gap, which is slow and small) and FX (the currency move, which is fast and large).
B8: 3. Shows why a 15 bp BOJ hike mattered as a SIGNAL rather than as a COST, with sensitivity grids.
B9: 4. Lays out the July–August 2024 timeline: the BOJ hike (31-Jul), the weak US ISM and payrolls prints (1–2 Aug) and Japan's 'Black Monday' (5-Aug).
B10: 5. Simulates a stylised deleveraging spiral: yen rally → losses → margin calls → forced yen buying → more yen rally.
B12: Sheet map
B13: 1_Carry_Mechanics: step-by-step P&L for three scenarios (Carry heaven: Jan–Jul 2024 | The unwind: 10-Jul to 5-Aug 2024 | Your own scenario).
B14: 2_Sensitivity: ROE by exit USD/JPY and leverage, plus the annual carry ROE by rate level. Compares a 15 bp hike with a 1% yen move.
B15: 3_Aug2024_Timeline: approximate daily closes for USD/JPY and the Nikkei 225, key events, returns and a chart.
... B43: • The unwind spiral uses stylised parameters, not estimates. Published estimates of the size of the yen carry trade in 2024 ranged from a few hundred billion to several trillion USD, depending on definition.

Sheet 1_Carry_Mechanics
A1: Yen Carry Trade: Step-by-Step Mechanics
A2: Borrow JPY cheaply → sell for USD → hold USD T-bills → at exit, buy back JPY and repay. Units: USD mm unless stated.
A4: Global assumptions
A5: Assumption | B5: Unit | C5: Value | F5: Source / note
A6: Investor equity (margin posted) | B6: USD mm | C6: 10 | F6: Illustrative hedge-fund sleeve.
A7: USD money-market rate (3M T-bill) | B7: % p.a. | C7: 0.053 | F7: ~5.3% in H1 2024; Fed funds target 5.25–5.50% (Jul-2023 to Sep-2024).
A8: BOJ policy rate, before the hike (upper bound) | B8: % p.a. | C8: 0.001 | F8: The 0–0.1% range set in Mar-2024, when negative rates ended.
A9: BOJ hike on 31-Jul-2024 | B9: % p.a. | C9: 0.0015 | F9: Raised to ~0.25%, i.e. +15 bp at the upper bound.
A10: BOJ policy rate, after the hike | B10: % p.a. | C10: =C8+C9 -> 0.0025 | F10: Formula.
A11: Day-count basis | B11: days | C11: 360 | F11: Simplification: ACT/360 for both legs (JPY market convention is ACT/365).
A12: Maintenance margin (equity / assets) | B12: % | C12: 0.05 | F12: Below this level the broker issues a margin call. Illustrative.
A14: Scenarios
A15: Line item | B15: Unit | C15: A: Carry heaven | D15: B: The unwind | E15: C: Your scenario | F15: Explanation
A16: Scenario | C16: 2-Jan to 10-Jul-2024 | D16: 10-Jul to 5-Aug-2024 | E16: Edit the yellow cells
A17: Leverage (assets / equity) | B17: x | C17: 10 | D17: 10 | E17: 3 | F17: Try 1x, 3x, 5x, 10x and 20x.
A18: Entry date | B18: date | C18: 45293 | D18: 45483 | E18: 45483
A19: Exit date | B19: date | C19: 45483 | D19: 45509 | E19: 45509
A20: Days held | B20: days | C20: =C19-C18 -> 190 | D20: =D19-D18 -> 26 | E20: =E19-E18 -> 26
A21: Entry USD/JPY | B21: ¥ per $ | C21: 141 | D21: 161.7 | E21: 161.7 | F21: Approx. NY closes. USD/JPY hit a 38-year high (~161.9) in early Jul-2024.
A22: Exit USD/JPY | B22: ¥ per $ | C22: 161.7 | D22: 144.2 | E22: 141.7 | F22: B: ~144.2 NY close on 5-Aug. C: ~141.7 was the intraday low on 5-Aug.
A23: Share of holding period after the BOJ hike | B23: % | C23: =MAX(0,C19-DATE(2024,7,31))/C20 -> 0 | D23: =MAX(0,D19-DATE(2024,7,31))/D20 -> 0.19230769 | E23: =MAX(0,E19-DATE(2024,7,31))/E20 -> 0.19230769 | F23: The post-hike rate applies only to days after 31-Jul-2024.
A24: Effective JPY funding rate | B24: % p.a. | C24: =$C$8+$C$9*C23 -> 0.001 | D24: =$C$8+$C$9*D23 -> 0.0012884615 | E24: =$C$8+$C$9*E23 -> 0.0012884615 | F24: Time-weighted mix of the pre-hike and post-hike rates.
A25: Interest-rate differential (USD − JPY) | B25: % p.a. | C25: =$C$7-C24 -> 0.052 | D25: =$C$7-D24 -> 0.051711538 | E25: =$C$7-E24 -> 0.051711538 | F25: The 'carry' the trade is paid to hold.
A26: Step 1: Put the trade on (at entry)
A27: USD T-bills bought | B27: USD mm | C27: =$C$6*C17 -> 100 | D27: =$C$6*D17 -> 100 | E27: =$C$6*E17 -> 30 | F27: Equity × leverage.
A28: funded by equity | B28: USD mm | C28: =$C$6 -> 10 | D28: =$C$6 -> 10 | E28: =$C$6 -> 10
A29: funded by the JPY loan | B29: USD mm | C29: =C27-C28 -> 90 | D29: =D27-D28 -> 90 | E29: =E27-E28 -> 20
A30: Yen borrowed | B30: ¥ mm | C30: =C29*C21 -> 12690 | D30: =D29*D21 -> 14553 | E30: =E29*E21 -> 3234 | F30: Borrow ¥ and sell them for $ at the entry rate.
A31: Step 2: Earn the carry
A32: USD interest earned | B32: USD mm | C32: =C27*$C$7*C20/$C$11 -> 2.7972222 | D32: =D27*$C$7*D20/$C$11 -> 0.38277778 | E32: =E27*$C$7*E20/$C$11 -> 0.11483333
A33: JPY interest owed | B33: ¥ mm | C33: =C30*C24*C20/$C$11 -> 6.6975 | D33: =D30*D24*D20/$C$11 -> 1.3542375 | E33: =E30*E24*E20/$C$11 -> 0.30094167
A34: JPY interest owed, at entry FX | B34: USD mm | C34: =C33/C21 -> 0.0475 | D34: =D33/D21 -> 0.008375 | E34: =E33/E21 -> 0.0018611111
A35: Net carry earned | B35: USD mm | C35: =C32-C34 -> 2.7497222 | D35: =D32-D34 -> 0.37440278 | E35: =E32-E34 -> 0.11297222 | F35: Small and steady: the 'nickels'.
A36: Step 3: Unwind (at exit)
A37: USD assets at exit (incl. interest) | B37: USD mm | C37: =C27+C32 -> 102.79722 | D37: =D27+D32 -> 100.38278 | E37: =E27+E32 -> 30.114833
A38: Yen to repay (principal + interest) | B38: ¥ mm | C38: =C30+C33 -> 12696.698 | D38: =D30+D33 -> 14554.354 | E38: =E30+E33 -> 3234.3009
A39: USD needed to buy back those yen | B39: USD mm | C39: =C38/C22 -> 78.520083 | D39: =D38/D22 -> 100.93172 | E39: =E38/E22 -> 22.824989 | F39: A lower USD/JPY (stronger yen) means more dollars are needed.
A40: Equity at exit | B40: USD mm | C40: =C37-C39 -> 24.277139 | D40: =D37-D39 -> -0.5489437 | E40: =E37-E39 -> 7.2898443 | F40: Negative means the investor owes more than the whole stake.
A41: Profit / (loss) | B41: USD mm | C41: =C40-$C$6 -> 14.277139 | D41: =D40-$C$6 -> -10.548944 | E41: =E40-$C$6 -> -2.7101557
A42: P&L attribution
...

Sheet 2_Sensitivity
A1: Sensitivity: the FX Move Dominates, Not the Rate Hike
A2: Parameters are linked (green) to Scenario B, 'The unwind', on 1_Carry_Mechanics. Change them there.
A4: Entry USD/JPY | B4: ='1_Carry_Mechanics'!D21 -> 161.7
A5: Days held | B5: ='1_Carry_Mechanics'!D20 -> 26
A6: USD rate | B6: ='1_Carry_Mechanics'!$C$7 -> 0.053
A7: Effective JPY rate | B7: ='1_Carry_Mechanics'!D24 -> 0.0012884615
A8: Day-count basis | B8: ='1_Carry_Mechanics'!$C$11 -> 360
A9: Leverage (Scenario B) | B9: ='1_Carry_Mechanics'!D17 -> 10
A10: BOJ hike | B10: ='1_Carry_Mechanics'!$C$9 -> 0.0015
A12: Table 1: Holding-period ROE by exit USD/JPY (rows) and leverage (columns)
A13: Exit USD/JPY \ Leverage → | B13: 1 | C13: 2 | D13: 3 | E13: 5 | F13: 10 | G13: 15 | H13: 20
A14: 135 | B14: =B$13*(1+$B$6*$B$5/$B$8)-(B$13-1)*($B$4/$A14)*(1+$B$7*$B$5/$B$8)-1 -> 0.0038277778 | C14: =C$13*(1+$B$6*$B$5/$B$8)-(C$13-1)*($B$4/$A14)*(1+$B$7*$B$5/$B$8)-1 -> -0.19023368 | D14: =D$13*(1+$B$6*$B$5/$B$8)-(D$13-1)*($B$4/$A14)*(1+$B$7*$B$5/$B$8)-1 -> -0.38429514 | E14: =E$13*(1+$B$6*$B$5/$B$8)-(E$13-1)*($B$4/$A14)*(1+$B$7*$B$5/$B$8)-1 -> -0.77241806 | F14: =F$13*(1+$B$6*$B$5/$B$8)-(F$13-1)*($B$4/$A14)*(1+$B$7*$B$5/$B$8)-1 -> -1.7427254 | G14: =G$13*(1+$B$6*$B$5/$B$8)-(G$13-1)*($B$4/$A14)*(1+$B$7*$B$5/$B$8)-1 -> -2.7130327 | H14: =H$13*(1+$B$6*$B$5/$B$8)-(H$13-1)*($B$4/$A14)*(1+$B$7*$B$5/$B$8)-1 -> -3.68334
A15: 137.5 | B15: =B$13*(1+$B$6*$B$5/$B$8)-(B$13-1)*($B$4/$A15)*(1+$B$7*$B$5/$B$8)-1 -> 0.0038277778 | C15: =C$13*(1+$B$6*$B$5/$B$8)-(C$13-1)*($B$4/$A15)*(1+$B$7*$B$5/$B$8)-1 -> -0.16845388 | D15: =D$13*(1+$B$6*$B$5/$B$8)-(D$13-1)*($B$4/$A15)*(1+$B$7*$B$5/$B$8)-1 -> -0.34073553 | E15: =E$13*(1+$B$6*$B$5/$B$8)-(E$13-1)*($B$4/$A15)*(1+$B$7*$B$5/$B$8)-1 -> -0.68529884 | F15: =F$13*(1+$B$6*$B$5/$B$8)-(F$13-1)*($B$4/$A15)*(1+$B$7*$B$5/$B$8)-1 -> -1.5467071 | G15: =G$13*(1+$B$6*$B$5/$B$8)-(G$13-1)*($B$4/$A15)*(1+$B$7*$B$5/$B$8)-1 -> -2.4081154 | H15: =H$13*(1+$B$6*$B$5/$B$8)-(H$13-1)*($B$4/$A15)*(1+$B$7*$B$5/$B$8)-1 -> -3.2695237
A16: 140 | B16: =B$13*(1+$B$6*$B$5/$B$8)-(B$13-1)*($B$4/$A16)*(1+$B$7*$B$5/$B$8)-1 -> 0.0038277778 | C16: =C$13*(1+$B$6*$B$5/$B$8)-(C$13-1)*($B$4/$A16)*(1+$B$7*$B$5/$B$8)-1 -> -0.14745192 | D16: =D$13*(1+$B$6*$B$5/$B$8)-(D$13-1)*($B$4/$A16)*(1+$B$7*$B$5/$B$8)-1 -> -0.29873162 | E16: =E$13*(1+$B$6*$B$5/$B$8)-(E$13-1)*($B$4/$A16)*(1+$B$7*$B$5/$B$8)-1 -> -0.60129103 | F16: =F$13*(1+$B$6*$B$5/$B$8)-(F$13-1)*($B$4/$A16)*(1+$B$7*$B$5/$B$8)-1 -> -1.3576895 | G16: =G$13*(1+$B$6*$B$5/$B$8)-(G$13-1)*($B$4/$A16)*(1+$B$7*$B$5/$B$8)-1 -> -2.114088 | H16: =H$13*(1+$B$6*$B$5/$B$8)-(H$13-1)*($B$4/$A16)*(1+$B$7*$B$5/$B$8)-1 -> -2.8704865
A17: 142.5 | B17: =B$13*(1+$B$6*$B$5/$B$8)-(B$13-1)*($B$4/$A17)*(1+$B$7*$B$5/$B$8)-1 -> 0.0038277778 | C17: =C$13*(1+$B$6*$B$5/$B$8)-(C$13-1)*($B$4/$A17)*(1+$B$7*$B$5/$B$8)-1 -> -0.12718688 | D17: =D$13*(1+$B$6*$B$5/$B$8)-(D$13-1)*($B$4/$A17)*(1+$B$7*$B$5/$B$8)-1 -> -0.25820154 | E17: =E$13*(1+$B$6*$B$5/$B$8)-(E$13-1)*($B$4/$A17)*(1+$B$7*$B$5/$B$8)-1 -> -0.52023085 | F17: =F$13*(1+$B$6*$B$5/$B$8)-(F$13-1)*($B$4/$A17)*(1+$B$7*$B$5/$B$8)-1 -> -1.1753041 | G17: =G$13*(1+$B$6*$B$5/$B$8)-(G$13-1)*($B$4/$A17)*(1+$B$7*$B$5/$B$8)-1 -> -1.8303774 | H17: =H$13*(1+$B$6*$B$5/$B$8)-(H$13-1)*($B$4/$A17)*(1+$B$7*$B$5/$B$8)-1 -> -2.4854507
A18: 145 | B18: =B$13*(1+$B$6*$B$5/$B$8)-(B$13-1)*($B$4/$A18)*(1+$B$7*$B$5/$B$8)-1 -> 0.0038277778 | C18: =C$13*(1+$B$6*$B$5/$B$8)-(C$13-1)*($B$4/$A18)*(1+$B$7*$B$5/$B$8)-1 -> -0.10762063 | D18: =D$13*(1+$B$6*$B$5/$B$8)-(D$13-1)*($B$4/$A18)*(1+$B$7*$B$5/$B$8)-1 -> -0.21906904 | E18: =E$13*(1+$B$6*$B$5/$B$8)-(E$13-1)*($B$4/$A18)*(1+$B$7*$B$5/$B$8)-1 -> -0.44196586 | F18: =F$13*(1+$B$6*$B$5/$B$8)-(F$13-1)*($B$4/$A18)*(1+$B$7*$B$5/$B$8)-1 -> -0.9992079 | G18: =G$13*(1+$B$6*$B$5/$B$8)-(G$13-1)*($B$4/$A18)*(1+$B$7*$B$5/$B$8)-1 -> -1.5564499 | H18: =H$13*(1+$B$6*$B$5/$B$8)-(H$13-1)*($B$4/$A18)*(1+$B$7*$B$5/$B$8)-1 -> -2.113692
A19: 147.5 | B19: =B$13*(1+$B$6*$B$5/$B$8)-(B$13-1)*($B$4/$A19)*(1+$B$7*$B$5/$B$8)-1 -> 0.0038277778 | C19: =C$13*(1+$B$6*$B$5/$B$8)-(C$13-1)*($B$4/$A19)*(1+$B$7*$B$5/$B$8)-1 -> -0.088717645 | D19: =D$13*(1+$B$6*$B$5/$B$8)-(D$13-1)*($B$4/$A19)*(1+$B$7*$B$5/$B$8)-1 -> -0.18126307 | E19: =E$13*(1+$B$6*$B$5/$B$8)-(E$13-1)*($B$4/$A19)*(1+$B$7*$B$5/$B$8)-1 -> -0.36635391 | F19: =F$13*(1+$B$6*$B$5/$B$8)-(F$13-1)*($B$4/$A19)*(1+$B$7*$B$5/$B$8)-1 -> -0.82908103 | G19: =G$13*(1+$B$6*$B$5/$B$8)-(G$13-1)*($B$4/$A19)*(1+$B$7*$B$5/$B$8)-1 -> -1.2918081 | H19: =H$13*(1+$B$6*$B$5/$B$8)-(H$13-1)*($B$4/$A19)*(1+$B$7*$B$5/$B$8)-1 -> -1.7545353
A20: 150 | B20: =B$13*(1+$B$6*$B$5/$B$8)-(B$13-1)*($B$4/$A20)*(1+$B$7*$B$5/$B$8)-1 -> 0.0038277778 | C20: =C$13*(1+$B$6*$B$5/$B$8)-(C$13-1)*($B$4/$A20)*(1+$B$7*$B$5/$B$8)-1 -> -0.070444758 | D20: =D$13*(1+$B$6*$B$5/$B$8)-(D$13-1)*($B$4/$A20)*(1+$B$7*$B$5/$B$8)-1 -> -0.14471729 | E20: =E$13*(1+$B$6*$B$5/$B$8)-(E$13-1)*($B$4/$A20)*(1+$B$7*$B$5/$B$8)-1 -> -0.29326237 | F20: =F$13*(1+$B$6*$B$5/$B$8)-(F$13-1)*($B$4/$A20)*(1+$B$7*$B$5/$B$8)-1 -> -0.66462505 | G20: =G$13*(1+$B$6*$B$5/$B$8)-(G$13-1)*($B$4/$A20)*(1+$B$7*$B$5/$B$8)-1 -> -1.0359877 | H20: =H$13*(1+$B$6*$B$5/$B$8)-(H$13-1)*($B$4/$A20)*(1+$B$7*$B$5/$B$8)-1 -> -1.4073504
A21: 152.5 | B21: =B$13*(1+$B$6*$B$5/$B$8)-(B$13-1)*($B$4/$A21)*(1+$B$7*$B$5/$B$8)-1 -> 0.0038277778 | C21: =C$13*(1+$B$6*$B$5/$B$8)-(C$13-1)*($B$4/$A21)*(1+$B$7*$B$5/$B$8)-1 -> -0.052770983 | D21: =D$13*(1+$B$6*$B$5/$B$8)-(D$13-1)*($B$4/$A21)*(1+$B$7*$B$5/$B$8)-1 -> -0.10936974 | E21: =E$13*(1+$B$6*$B$5/$B$8)-(E$13-1)*($B$4/$A21)*(1+$B$7*$B$5/$B$8)-1 -> -0.22256726 | F21: =F$13*(1+$B$6*$B$5/$B$8)-(F$13-1)*($B$4/$A21)*(1+$B$7*$B$5/$B$8)-1 -> -0.50556107 | G21: =G$13*(1+$B$6*$B$5/$B$8)-(G$13-1)*($B$4/$A21)*(1+$B$7*$B$5/$B$8)-1 -> -0.78855487 | H21: =H$13*(1+$B$6*$B$5/$B$8)-(H$13-1)*($B$4/$A21)*(1+$B$7*$B$5/$B$8)-1 -> -1.0715487
A22: 155 | B22: =B$13*(1+$B$6*$B$5/$B$8)-(B$13-1)*($B$4/$A22)*(1+$B$7*$B$5/$B$8)-1 -> 0.0038277778 | C22: =C$13*(1+$B$6*$B$5/$B$8)-(C$13-1)*($B$4/$A22)*(1+$B$7*$B$5/$B$8)-1 -> -0.035667329 | D22: =D$13*(1+$B$6*$B$5/$B$8)-(D$13-1)*($B$4/$A22)*(1+$B$7*$B$5/$B$8)-1 -> -0.075162435 | E22: =E$13*(1+$B$6*$B$5/$B$8)-(E$13-1)*($B$4/$A22)*(1+$B$7*$B$5/$B$8)-1 -> -0.15415265 | F22: =F$13*(1+$B$6*$B$5/$B$8)-(F$13-1)*($B$4/$A22)*(1+$B$7*$B$5/$B$8)-1 -> -0.35162818 | G22: =G$13*(1+$B$6*$B$5/$B$8)-(G$13-1)*($B$4/$A22)*(1+$B$7*$B$5/$B$8)-1 -> -0.54910372 | H22: =H$13*(1+$B$6*$B$5/$B$8)-(H$13-1)*($B$4/$A22)*(1+$B$7*$B$5/$B$8)-1 -> -0.74657925
A23: 157.5 | B23: =B$13*(1+$B$6*$B$5/$B$8)-(B$13-1)*($B$4/$A23)*(1+$B$7*$B$5/$B$8)-1 -> 0.0038277778 | C23: =C$13*(1+$B$6*$B$5/$B$8)-(C$13-1)*($B$4/$A23)*(1+$B$7*$B$5/$B$8)-1 -> -0.019106648 | D23: =D$13*(1+$B$6*$B$5/$B$8)-(D$13-1)*($B$4/$A23)*(1+$B$7*$B$5/$B$8)-1 -> -0.042041074 | E23: =E$13*(1+$B$6*$B$5/$B$8)-(E$13-1)*($B$4/$A23)*(1+$B$7*$B$5/$B$8)-1 -> -0.087909926 | F23: =F$13*(1+$B$6*$B$5/$B$8)-(F$13-1)*($B$4/$A23)*(1+$B$7*$B$5/$B$8)-1 -> -0.20258206 | G23: =G$13*(1+$B$6*$B$5/$B$8)-(G$13-1)*($B$4/$A23)*(1+$B$7*$B$5/$B$8)-1 -> -0.31725419 | H23: =H$13*(1+$B$6*$B$5/$B$8)-(H$13-1)*($B$4/$A23)*(1+$B$7*$B$5/$B$8)-1 -> -0.43192631
A24: 160 | B24: =B$13*(1+$B$6*$B$5/$B$8)-(B$13-1)*($B$4/$A24)*(1+$B$7*$B$5/$B$8)-1 -> 0.0038277778 | C24: =C$13*(1+$B$6*$B$5/$B$8)-(C$13-1)*($B$4/$A24)*(1+$B$7*$B$5/$B$8)-1 -> -0.0030634887 | D24: =D$13*(1+$B$6*$B$5/$B$8)-(D$13-1)*($B$4/$A24)*(1+$B$7*$B$5/$B$8)-1 -> -0.0099547552 | E24: =E$13*(1+$B$6*$B$5/$B$8)-(E$13-1)*($B$4/$A24)*(1+$B$7*$B$5/$B$8)-1 -> -0.023737288 | F24: =F$13*(1+$B$6*$B$5/$B$8)-(F$13-1)*($B$4/$A24)*(1+$B$7*$B$5/$B$8)-1 -> -0.058193621 | G24: =G$13*(1+$B$6*$B$5/$B$8)-(G$13-1)*($B$4/$A24)*(1+$B$7*$B$5/$B$8)-1 -> -0.092649953 | H24: =H$13*(1+$B$6*$B$5/$B$8)-(H$13-1)*($B$4/$A24)*(1+$B$7*$B$5/$B$8)-1 -> -0.12710629
A25: 161.7 | B25: =B$13*(1+$B$6*$B$5/$B$8)-(B$13-1)*($B$4/$A25)*(1+$B$7*$B$5/$B$8)-1 -> 0.0038277778 | C25: =C$13*(1+$B$6*$B$5/$B$8)-(C$13-1)*($B$4/$A25)*(1+$B$7*$B$5/$B$8)-1 -> 0.0075625 | D25: =D$13*(1+$B$6*$B$5/$B$8)-(D$13-1)*($B$4/$A25)*(1+$B$7*$B$5/$B$8)-1 -> 0.011297222 | E25: =E$13*(1+$B$6*$B$5/$B$8)-(E$13-1)*($B$4/$A25)*(1+$B$7*$B$5/$B$8)-1 -> 0.018766667 | F25: =F$13*(1+$B$6*$B$5/$B$8)-(F$13-1)*($B$4/$A25)*(1+$B$7*$B$5/$B$8)-1 -> 0.037440278 | G25: =G$13*(1+$B$6*$B$5/$B$8)-(G$13-1)*($B$4/$A25)*(1+$B$7*$B$5/$B$8)-1 -> 0.056113889 | H25: =H$13*(1+$B$6*$B$5/$B$8)-(H$13-1)*($B$4/$A25)*(1+$B$7*$B$5/$B$8)-1 -> 0.0747875
... A27: 167.5 | B27: =B$13*(1+$B$6*$B$5/$B$8)-(B$13-1)*($B$4/$A27)*(1+$B$7*$B$5/$B$8)-1 -> 0.0038277778 | C27: =C$13*(1+$B$6*$B$5/$B$8)-(C$13-1)*($B$4/$A27)*(1+$B$7*$B$5/$B$8)-1 -> 0.042192588 | D27: =D$13*(1+$B$6*$B$5/$B$8)-(D$13-1)*($B$4/$A27)*(1+$B$7*$B$5/$B$8)-1 -> 0.080557398 | E27: =E$13*(1+$B$6*$B$5/$B$8)-(E$13-1)*($B$4/$A27)*(1+$B$7*$B$5/$B$8)-1 -> 0.15728702 | F27: =F$13*(1+$B$6*$B$5/$B$8)-(F$13-1)*($B$4/$A27)*(1+$B$7*$B$5/$B$8)-1 -> 0.34911107 | G27: =G$13*(1+$B$6*$B$5/$B$8)-(G$13-1)*($B$4/$A27)*(1+$B$7*$B$5/$B$8)-1 -> 0.54093512 | H27: =H$13*(1+$B$6*$B$5/$B$8)-(H$13-1)*($B$4/$A27)*(1+$B$7*$B$5/$B$8)-1 -> 0.73275917
A28: Formula: ROE = L·(1 + r$·t) − (L − 1)·(S0 / S1)·(1 + r¥·t) − 1. Any ROE below −100% means the investor loses more than the whole stake.
A30: Table 2: Annual carry-only ROE (FX unchanged) by JPY rate (rows) and USD rate (columns), at Scenario B leverage
A31: JPY rate \ USD rate → | B31: 0.03 | C31: 0.04 | D31: 0.045 | E31: 0.05 | F31: 0.053 | G31: 0.055
A32: 0 | B32: =$B$9*B$31-($B$9-1)*$A32 -> 0.3 | C32: =$B$9*C$31-($B$9-1)*$A32 -> 0.4 | D32: =$B$9*D$31-($B$9-1)*$A32 -> 0.45 | E32: =$B$9*E$31-($B$9-1)*$A32 -> 0.5 | F32: =$B$9*F$31-($B$9-1)*$A32 -> 0.53 | G32: =$B$9*G$31-($B$9-1)*$A32 -> 0.55
A33: 0.001 | B33: =$B$9*B$31-($B$9-1)*$A33 -> 0.291 | C33: =$B$9*C$31-($B$9-1)*$A33 -> 0.391 | D33: =$B$9*D$31-($B$9-1)*$A33 -> 0.441 | E33: =$B$9*E$31-($B$9-1)*$A33 -> 0.491 | F33: =$B$9*F$31-($B$9-1)*$A33 -> 0.521 | G33: =$B$9*G$31-($B$9-1)*$A33 -> 0.541
A34: 0.0025 | B34: =$B$9*B$31-($B$9-1)*$A34 -> 0.2775 | C34: =$B$9*C$31-($B$9-1)*$A34 -> 0.3775 | D34: =$B$9*D$31-($B$9-1)*$A34 -> 0.4275 | E34: =$B$9*E$31-($B$9-1)*$A34 -> 0.4775 | F34: =$B$9*F$31-($B$9-1)*$A34 -> 0.5075 | G34: =$B$9*G$31-($B$9-1)*$A34 -> 0.5275
A35: 0.005 | B35: =$B$9*B$31-($B$9-1)*$A35 -> 0.255 | C35: =$B$9*C$31-($B$9-1)*$A35 -> 0.355 | D35: =$B$9*D$31-($B$9-1)*$A35 -> 0.405 | E35: =$B$9*E$31-($B$9-1)*$A35 -> 0.455 | F35: =$B$9*F$31-($B$9-1)*$A35 -> 0.485 | G35: =$B$9*G$31-($B$9-1)*$A35 -> 0.505
A36: 0.0075 | B36: =$B$9*B$31-($B$9-1)*$A36 -> 0.2325 | C36: =$B$9*C$31-($B$9-1)*$A36 -> 0.3325 | D36: =$B$9*D$31-($B$9-1)*$A36 -> 0.3825 | E36: =$B$9*E$31-($B$9-1)*$A36 -> 0.4325 | F36: =$B$9*F$31-($B$9-1)*$A36 -> 0.4625 | G36: =$B$9*G$31-($B$9-1)*$A36 -> 0.4825
A37: 0.01 | B37: =$B$9*B$31-($B$9-1)*$A37 -> 0.21 | C37: =$B$9*C$31-($B$9-1)*$A37 -> 0.31 | D37: =$B$9*D$31-($B$9-1)*$A37 -> 0.36 | E37: =$B$9*E$31-($B$9-1)*$A37 -> 0.41 | F37: =$B$9*F$31-($B$9-1)*$A37 -> 0.44 | G37: =$B$9*G$31-($B$9-1)*$A37 -> 0.46
A38: 0.02 | B38: =$B$9*B$31-($B$9-1)*$A38 -> 0.12 | C38: =$B$9*C$31-($B$9-1)*$A38 -> 0.22 | D38: =$B$9*D$31-($B$9-1)*$A38 -> 0.27 | E38: =$B$9*E$31-($B$9-1)*$A38 -> 0.32 | F38: =$B$9*F$31-($B$9-1)*$A38 -> 0.35 | G38: =$B$9*G$31-($B$9-1)*$A38 -> 0.37
A40: The punchline: the signal versus the cost
A41: Annual ROE cost of the 15 bp BOJ hike | B41: =($B$9-1)*$B$10 -> 0.0135 | C41: (L − 1) × hike. Paid gradually over a whole year.
A42: Instant ROE cost of a 1% yen rally | B42: =($B$9-1)*1% -> 0.09 | C42: ≈ (L − 1) × 1%. Paid overnight.
A43: Instant ROE cost of the actual yen rally (Scenario B) | B43: =-'1_Carry_Mechanics'!D46+'1_Carry_Mechanics'!D35/'1_Carry_Mechanics'!$C$6 -> 1.0923346 | C43: FX loss as a % of equity for Scenario B (roughly 12% yen × 9 turns of yen debt).
A44: FX shock ÷ hike cost (times) | B44: =IF(B41>0,B43/B41,0) -> 80.913678 | C44: The hike mattered because it changed EXPECTATIONS and triggered crowded exits, not because of its cost.

Sheet 3_Aug2024_Timeline
A1: July–August 2024: From the Carry Peak to Japan's 'Black Monday'
A2: USD/JPY: approximate NY closes. Nikkei 225: official closes. Verify against Bloomberg or FRED (DEXJPUS) before quoting to the decimal.
A4: Date | B4: USD/JPY | C4: Nikkei 225 | D4: USD/JPY chg | E4: Nikkei chg | F4: Nikkei vs 31-Jul close | G4: Yen apprec. vs 10-Jul | H4: What happened
A5: 45483 | B5: 161.7 | C5: 41831.99 | F5: =C5/$C$8-1 -> 0.06982207 | G5: =$B$5/B5-1 -> 0 | H5: Carry at its peak. USD/JPY near a 38-year high. CFTC speculative net yen shorts near their largest since 2007.
A6: 45484 | B6: 158.9 | C6: 42224.02 | D6: =B6/B5-1 -> -0.017316017 | E6: =C6/C5-1 -> 0.009371536 | F6: =C6/$C$8-1 -> 0.079847946 | G6: =$B$5/B6-1 -> 0.017621145 | H6: Nikkei record close. Soft US June CPI. Suspected MOF yen-buying intervention (later confirmed at ~¥5.5trn over 11–12 Jul).
A7: 45503 | B7: 152.7 | C7: 38525.95 | D7: =B7/B6-1 -> -0.03901825 | E7: =C7/C6-1 -> -0.087582139 | F7: =C7/$C$8-1 -> -0.014727447 | G7: =$B$5/B7-1 -> 0.058939096 | H7: BOJ meeting, day 1. Yen already firming as carry positions start to be cut.
A8: 45504 | B8: 150 | C8: 39101.82 | D8: =B8/B7-1 -> -0.017681729 | E8: =C8/C7-1 -> 0.014947587 | F8: =C8/$C$8-1 -> 0 | G8: =$B$5/B8-1 -> 0.078 | H8: BOJ HIKES to ~0.25% (+15 bp) and sets a plan to halve JGB buying. Gov. Ueda sounds hawkish. Fed holds at 5.25–5.50% and hints at a September cut.
A9: 45505 | B9: 149.4 | C9: 38126.33 | D9: =B9/B8-1 -> -0.004 | E9: =C9/C8-1 -> -0.024947432 | F9: =C9/$C$8-1 -> -0.024947432 | G9: =$B$5/B9-1 -> 0.082329317 | H9: US ISM Manufacturing weak at 46.8. Growth scare begins. Session 1 of 3.
A10: 45506 | B10: 146.5 | C10: 35909.7 | D10: =B10/B9-1 -> -0.019410977 | E10: =C10/C9-1 -> -0.058139087 | F10: =C10/$C$8-1 -> -0.081636098 | G10: =$B$5/B10-1 -> 0.10375427 | H10: US July payrolls +114k against ~175k expected, unemployment 4.3%: the 'Sahm rule' recession trigger. Session 2 of 3.
A11: 45509 | B11: 144.2 | C11: 31458.42 | D11: =B11/B10-1 -> -0.015699659 | E11: =C11/C10-1 -> -0.12395759 | F11: =C11/$C$8-1 -> -0.19547428 | G11: =$B$5/B11-1 -> 0.12135922 | H11: JAPAN'S BLACK MONDAY: Nikkei −12.4%, −4,451 pts (largest point drop ever). TOPIX −12.2%. Circuit breakers hit. VIX intraday ~65. USD/JPY intraday low ~141.7. Session 3 of 3.
A12: 45510 | B12: 144.3 | C12: 34675.46 | D12: =B12/B11-1 -> 0.00069348128 | E12: =C12/C11-1 -> 0.10226324 | F12: =C12/$C$8-1 -> -0.11320087 | G12: =$B$5/B12-1 -> 0.12058212 | H12: Snap-back: Nikkei +10.2%, its largest point gain ever.
A13: 45511 | B13: 146.7 | C13: 35089.62 | D13: =B13/B12-1 -> 0.016632017 | E13: =C13/C12-1 -> 0.011943893 | F13: =C13/$C$8-1 -> -0.10260903 | G13: =$B$5/B13-1 -> 0.10224949 | H13: BOJ Deputy Gov. Uchida: 'will not raise rates when markets are unstable'. The central-bank put is restored.
A15: Episode statistics
A16: Nikkei, 5-Aug single session | D16: =E11 -> -0.12395759 | E16: The famous '−12%' day.
A17: Nikkei, 3 sessions (31-Jul close → 5-Aug close) | D17: =C11/C8-1 -> -0.19547428 | E17: The cumulative fall over 1, 2 and 5 Aug was about −19.5%. The ~12% figure often quoted is the 5-Aug fall alone.
A18: Nikkei, peak to trough (11-Jul record → 5-Aug) | D18: =C11/C6-1 -> -0.25496388 | E18: Bear-market territory in under 4 weeks.
A19: Nikkei, 6-Aug rebound | D19: =E12 -> 0.10226324 | E19: Most of the 'information' in the crash was flow, not fundamentals.
A20: Nikkei point drop on 5-Aug | D20: =C11-C10 -> -4451.28 | E20: Larger in points than 19-Oct-1987 (−3,836).
A21: Yen appreciation, 10-Jul → 5-Aug | D21: =G11 -> 0.12135922 | E21: Compare with the ~11% wipe-out threshold on 1_Carry_Mechanics.
A22: Nikkei % move per 1% yen rally (10-Jul → 5-Aug) | D22: =-(C11/C5-1)/G11 -> 2.0433696 | E22: A rough 'beta' used as the default input on 4_Unwind_Spiral.

Sheet 4_Unwind_Spiral
A1: Stylised Deleveraging Spiral: Reflexivity in Action
A2: Shock → yen rally → losses on yen debt → equity falls → leverage too high → sell USD assets and BUY YEN → yen rallies further → …
A4: Inputs (stylised, for illustration only)
A5: Aggregate carry positions (USD bn) | B5: 500 | C5: Illustrative. Published estimates range from a few hundred billion to several trillion USD.
A6: Target leverage (assets / equity) | B6: 10 | C6: Funds must stay at or below this leverage, so losses force sales.
A7: Initial shock: yen appreciation | B7: 0.04 | C7: The combined surprise of the BOJ hike, US data and MOF intervention.
A8: Price impact: yen rally per USD 100bn of forced yen buying | B8: 0.02 | C8: Market depth. Lower in thin August markets.
A9: Nikkei % fall per 1% yen rally | B9: ='3_Aug2024_Timeline'!D22 -> 2.0433696 | C9: Linked to the episode's realised ratio. Change it to a number to override.
A10: Starting USD/JPY (10-Jul-2024) | B10: ='3_Aug2024_Timeline'!B5 -> 161.7
A11: Starting Nikkei 225 (10-Jul-2024) | B11: ='3_Aug2024_Timeline'!C5 -> 41831.99
A12: Implied starting equity (USD bn) | B12: =B5/B6 -> 50
A13: Stability factor (impact × leverage × yen debt ÷ 100) | B13: =B8*B6*(B5-B12)/100 -> 0.9 | C13: Above 1, each round of selling causes a BIGGER next round, and the spiral runs until the equity is gone.
A15: Rounds of forced deleveraging (USD bn)
A16: Round | B16: Assets (start) | C16: Yen debt (start) | D16: Equity (start) | E16: Yen rally this round | F16: Loss on yen debt | G16: Equity after loss | H16: Target assets | I16: Forced unwind (buy ¥) | J16: Cum. yen rally | K16: USD/JPY | L16: Stylised Nikkei
A17: 0 | B17: =$B$5 -> 500 | C17: =B17-D17 -> 450 | D17: =$B$12 -> 50 | E17: =$B$7 -> 0.04 | F17: =MAX(0,C17)*E17 -> 18 | G17: =D17-F17 -> 32 | H17: =MAX(0,$B$6*G17) -> 320 | I17: =MAX(0,B17-H17) -> 180 | J17: =E17 -> 0.04 | K17: =$B$10/(1+J17) -> 155.48077 | L17: =MAX(0,$B$11*(1-$B$9*J17)) -> 38412.861
A18: 1 | B18: =H17 -> 320 | C18: =C17+F17-I17 -> 288 | D18: =G17 -> 32 | E18: =$B$8*I17/100 -> 0.036 | F18: =MAX(0,C18)*E18 -> 10.368 | G18: =D18-F18 -> 21.632 | H18: =MAX(0,$B$6*G18) -> 216.32 | I18: =MAX(0,B18-H18) -> 103.68 | J18: =(1+J17)*(1+E18)-1 -> 0.07744 | K18: =$B$10/(1+J18) -> 150.07796 | L18: =MAX(0,$B$11*(1-$B$9*J18)) -> 35212.557
A19: 2 | B19: =H18 -> 216.32 | C19: =C18+F18-I18 -> 194.688 | D19: =G18 -> 21.632 | E19: =$B$8*I18/100 -> 0.020736 | F19: =MAX(0,C19)*E19 -> 4.0370504 | G19: =D19-F19 -> 17.59495 | H19: =MAX(0,$B$6*G19) -> 175.9495 | I19: =MAX(0,B19-H19) -> 40.370504 | J19: =(1+J18)*(1+E19)-1 -> 0.099781796 | K19: =$B$10/(1+J19) -> 147.02917 | L19: =MAX(0,$B$11*(1-$B$9*J19)) -> 33302.82
A20: 3 | B20: =H19 -> 175.9495 | C20: =C19+F19-I19 -> 158.35455 | D20: =G19 -> 17.59495 | E20: =$B$8*I19/100 -> 0.0080741007 | F20: =MAX(0,C20)*E20 -> 1.2785706 | G20: =D20-F20 -> 16.316379 | H20: =MAX(0,$B$6*G20) -> 163.16379 | I20: =MAX(0,B20-H20) -> 12.785706 | J20: =(1+J19)*(1+E20)-1 -> 0.10866154 | K20: =$B$10/(1+J20) -> 145.85155 | L20: =MAX(0,$B$11*(1-$B$9*J20)) -> 32543.795
A21: 4 | B21: =H20 -> 163.16379 | C21: =C20+F20-I20 -> 146.84741 | D21: =G20 -> 16.316379 | E21: =$B$8*I20/100 -> 0.0025571411 | F21: =MAX(0,C21)*E21 -> 0.37550956 | G21: =D21-F21 -> 15.94087 | H21: =MAX(0,$B$6*G21) -> 159.4087 | I21: =MAX(0,B21-H21) -> 3.7550956 | J21: =(1+J20)*(1+E21)-1 -> 0.11149655 | K21: =$B$10/(1+J21) -> 145.47953 | L21: =MAX(0,$B$11*(1-$B$9*J21)) -> 32301.464
A22: 5 | B22: =H21 -> 159.4087 | C22: =C21+F21-I21 -> 143.46783 | D22: =G21 -> 15.94087 | E22: =$B$8*I21/100 -> 0.00075101911 | F22: =MAX(0,C22)*E22 -> 0.10774708 | G22: =D22-F22 -> 15.833122 | H22: =MAX(0,$B$6*G22) -> 158.33122 | I22: =MAX(0,B22-H22) -> 1.0774708 | J22: =(1+J21)*(1+E22)-1 -> 0.1123313 | K22: =$B$10/(1+J22) -> 145.37036 | L22: =MAX(0,$B$11*(1-$B$9*J22)) -> 32230.11
A23: 6 | B23: =H22 -> 158.33122 | C23: =C22+F22-I22 -> 142.4981 | D23: =G22 -> 15.833122 | E23: =$B$8*I22/100 -> 0.00021549416 | F23: =MAX(0,C23)*E23 -> 0.030707508 | G23: =D23-F23 -> 15.802415 | H23: =MAX(0,$B$6*G23) -> 158.02415 | I23: =MAX(0,B23-H23) -> 0.30707508 | J23: =(1+J22)*(1+E23)-1 -> 0.112571 | K23: =$B$10/(1+J23) -> 145.33904 | L23: =MAX(0,$B$11*(1-$B$9*J23)) -> 32209.621
A24: 7 | B24: =H23 -> 158.02415 | C24: =C23+F23-I23 -> 142.22173 | D24: =G23 -> 15.802415 | E24: =$B$8*I23/100 -> 6.1415017e-05 | F24: =MAX(0,C24)*E24 -> 0.0087345502 | G24: =D24-F24 -> 15.79368 | H24: =MAX(0,$B$6*G24) -> 157.9368 | I24: =MAX(0,B24-H24) -> 0.087345502 | J24: =(1+J23)*(1+E24)-1 -> 0.11263933 | K24: =$B$10/(1+J24) -> 145.33011 | L24: =MAX(0,$B$11*(1-$B$9*J24)) -> 32203.781
A25: 8 | B25: =H24 -> 157.9368 | C25: =C24+F24-I24 -> 142.14312 | D25: =G24 -> 15.79368 | E25: =$B$8*I24/100 -> 1.74691e-05 | F25: =MAX(0,C25)*E25 -> 0.0024831125 | G25: =D25-F25 -> 15.791197 | H25: =MAX(0,$B$6*G25) -> 157.91197 | I25: =MAX(0,B25-H25) -> 0.024831125 | J25: =(1+J24)*(1+E25)-1 -> 0.11265877 | K25: =$B$10/(1+J25) -> 145.32757 | L25: =MAX(0,$B$11*(1-$B$9*J25)) -> 32202.119
A26: 9 | B26: =H25 -> 157.91197 | C26: =C25+F25-I25 -> 142.12078 | D26: =G25 -> 15.791197 | E26: =$B$8*I25/100 -> 4.966225e-06 | F26: =MAX(0,C26)*E26 -> 0.00070580375 | G26: =D26-F26 -> 15.790491 | H26: =MAX(0,$B$6*G26) -> 157.90491 | I26: =MAX(0,B26-H26) -> 0.0070580375 | J26: =(1+J25)*(1+E26)-1 -> 0.1126643 | K26: =$B$10/(1+J26) -> 145.32685 | L26: =MAX(0,$B$11*(1-$B$9*J26)) -> 32201.647
A27: 10 | B27: =H26 -> 157.90491 | C27: =C26+F26-I26 -> 142.11442 | D27: =G26 -> 15.790491 | E27: =$B$8*I26/100 -> 1.4116075e-06 | F27: =MAX(0,C27)*E27 -> 0.00020060978 | G27: =D27-F27 -> 15.790291 | H27: =MAX(0,$B$6*G27) -> 157.90291 | I27: =MAX(0,B27-H27) -> 0.0020060978 | J27: =(1+J26)*(1+E27)-1 -> 0.11266587 | K27: =$B$10/(1+J27) -> 145.32665 | L27: =MAX(0,$B$11*(1-$B$9*J27)) -> 32201.513
A29: Outcome
A30: Total yen appreciation | B30: =J27 -> 0.11266587 | C30: Compare: ~12% actual (10-Jul → 5-Aug close).
A31: Amplification multiple (total ÷ initial shock) | B31: =J27/B7 -> 2.8166467 | C31: How much the spiral magnified the original news.
A32: Share of carry positions forcibly unwound | B32: =SUM(I17:I27)/B5 -> 0.68419418 | C32: Several banks estimated at the time that half or more of carry positions had been unwound by mid-August.
A33: Final USD/JPY | B33: =K27 -> 145.32665
A34: Stylised Nikkei (final) | B34: =L27 -> 32201.513 | C34: Actual 5-Aug close: 31,458.
A35: Equity remaining (% of start) | B35: =G27/B12 -> 0.31580582 | C35: Survivors keep their equity but hold much smaller books.
A37: Try: set the price impact to 3.0%. The stability factor rises above 1 and the spiral wipes out most of the equity. Then set leverage to 3x. Lower leverage is the only thing that breaks the loop.
